Workbook

Sheet Report
H18: `

Sheet Linearity Data
A2: Input Data | E2: Output
A3: Exp/ Light Level | B3: Gray Value (uy-Uy.dark) | C3: Temporal STD | D3: Total STD | E3: Index | F3: Gray Value (uy-Uy.dark) | G3: STD | H3: STD CHK | I3: Variance gray | J3: Variance Fit | L3: photons | M3: SNR(linear) | R3: Linearity Error(%)
H4: STD CHK | J4: GrayValue | K4: Variance slop | O4: SNR Db
E5: 0 | F5: =IF(G5="","",B5) | G5: =IF(SUM($H4:H$5)<1,C5,"") | H5: =IF(MAX($C$5:$C$105)=C5,1,"") -> 1 | I5: =C5^2-$C$5^2 -> 0 | J5: =IF(AND($V$40>F5,NOT(G5="")),F5,"") -> #N/A | K5: =IF(AND($V$40>F5,NOT(G5="")),I5,"") -> #N/A | L5: =IF(G5="","",G5*$V$6*(100/$V$5)) | M5: 1 | N5: 1 | O5: =LOG10(M5)*20 -> 0 | P5: 0 | Q5: =LOG10(M5)*20 -> 0 | R5: =IF(F5="","",(F5-(E5*$V$71+$V$72))*100/(MAX($F$5:$F$105)*0.9)) | U5: Quamtum Eppiciency | V5: 88.4
E6: =IF(F6="","",E5+1) | F6: =IF(G6="","",B6) | G6: =IF(SUM($H5:H$5)<1,C6,"") | H6: =IF(MAX($C$5:$C$105)=C6,1,"") -> 1 | I6: =C6^2-$C$5^2 -> 0 | J6: =IF(AND($V$40>F6,NOT(G6="")),F6,"") -> #N/A | K6: =IF(AND($V$40>F6,NOT(G6="")),I6,"") -> #N/A | L6: =IF(G6="",L5,F6*$V$6*(100/$V$5)) | M6: =IF(G6="",M5,(F6-$F$5)/G6) -> 1 | N6: =IF(G6="",M5,(F6-$F$5)/D6) -> 1 | O6: =LOG10(M6)*20 -> 0 | P6: =LOG10(N6)*20 -> 0 | R6: =IF(F6="","",(F6-(E6*$V$71+$V$72))*100/(MAX($F$5:$F$105)*0.9)) | U6: System Gain | V6: =1/((MATCH(MAX(K5:K105),K5:K105)*SUMPRODUCT(J5:J105,K5:K105)-SUM(J5:J105)*SUM(K5:K105))/(MATCH(MAX(K5:K105),K5:K105)*SUMSQ(J5:J105) - SUM(J5:J105)^2)) -> #N/A
E7: =IF(F7="","",E6+1) | F7: =IF(G7="","",B7) | G7: =IF(SUM($H$5:H6)<1,C7,"") | H7: =IF(MAX($C$5:$C$105)=C7,1,"") -> 1 | I7: =C7^2-$C$5^2 -> 0 | J7: =IF(AND($V$40>F7,NOT(G7="")),F7,"") -> #N/A | K7: =IF(AND($V$40>F7,NOT(G7="")),I7,"") -> #N/A | L7: =IF(G7="",L6,F7*$V$6*(100/$V$5)) | M7: =IF(G7="",M6,(F7-$F$5)/G7) -> 1 | N7: =IF(G7="",M6,(F7-$F$5)/D7) -> 1 | O7: =LOG10(M7)*20 -> 0 | P7: =LOG10(N7)*20 -> 0 | R7: =IF(F7="","",(F7-(E7*$V$71+$V$72))*100/(MAX($F$5:$F$105)*0.9))
E8: =IF(F8="","",E7+1) | F8: =IF(G8="","",B8) | G8: =IF(SUM($H$5:H7)<1,C8,"") | H8: =IF(MAX($C$5:$C$105)=C8,1,"") -> 1 | I8: =C8^2-$C$5^2 -> 0 | J8: =IF(AND($V$40>F8,NOT(G8="")),F8,"") -> #N/A | K8: =IF(AND($V$40>F8,NOT(G8="")),I8,"") -> #N/A | L8: =IF(G8="",L7,F8*$V$6*(100/$V$5)) | M8: =IF(G8="",M7,(F8-$F$5)/G8) -> 1 | N8: =IF(G8="",M7,(F8-$F$5)/D8) -> 1 | O8: =LOG10(M8)*20 -> 0 | P8: =LOG10(N8)*20 -> 0 | R8: =IF(F8="","",(F8-(E8*$V$71+$V$72))*100/(MAX($F$5:$F$105)*0.9))
E9: =IF(F9="","",E8+1) | F9: =IF(G9="","",B9) | G9: =IF(SUM($H$5:H8)<1,C9,"") | H9: =IF(MAX($C$5:$C$105)=C9,1,"") -> 1 | I9: =C9^2-$C$5^2 -> 0 | J9: =IF(AND($V$40>F9,NOT(G9="")),F9,"") -> #N/A | K9: =IF(AND($V$40>F9,NOT(G9="")),I9,"") -> #N/A | L9: =IF(G9="",L8,F9*$V$6*(100/$V$5)) | M9: =IF(G9="",M8,(F9-$F$5)/G9) -> 1 | N9: =IF(G9="",M8,(F9-$F$5)/D9) -> 1 | O9: =LOG10(M9)*20 -> 0 | P9: =LOG10(N9)*20 -> 0 | R9: =IF(F9="","",(F9-(E9*$V$71+$V$72))*100/(MAX($F$5:$F$105)*0.9))
E10: =IF(F10="","",E9+1) | F10: =IF(G10="","",B10) | G10: =IF(SUM($H$5:H9)<1,C10,"") | H10: =IF(MAX($C$5:$C$105)=C10,1,"") -> 1 | I10: =C10^2-$C$5^2 -> 0 | J10: =IF(AND($V$40>F10,NOT(G10="")),F10,"") -> #N/A | K10: =IF(AND($V$40>F10,NOT(G10="")),I10,"") -> #N/A | L10: =IF(G10="",L9,F10*$V$6*(100/$V$5)) | M10: =IF(G10="",M9,(F10-$F$5)/G10) -> 1 | N10: =IF(G10="",M9,(F10-$F$5)/D10) -> 1 | O10: =LOG10(M10)*20 -> 0 | P10: =LOG10(N10)*20 -> 0 | R10: =IF(F10="","",(F10-(E10*$V$71+$V$72))*100/(MAX($F$5:$F$105)*0.9)) | U10: DSNU1288 | V10: =SQRT(V13)*V6 -> #N/A | W10: e-
E11: =IF(F11="","",E10+1) | F11: =IF(G11="","",B11) | G11: =IF(SUM($H$5:H10)<1,C11,"") | H11: =IF(MAX($C$5:$C$105)=C11,1,"") -> 1 | I11: =C11^2-$C$5^2 -> 0 | J11: =IF(AND($V$40>F11,NOT(G11="")),F11,"") -> #N/A | K11: =IF(AND($V$40>F11,NOT(G11="")),I11,"") -> #N/A | L11: =IF(G11="",L10,F11*$V$6*(100/$V$5)) | M11: =IF(G11="",M10,(F11-$F$5)/G11) -> 1 | N11: =IF(G11="",M10,(F11-$F$5)/D11) -> 1 | O11: =LOG10(M11)*20 -> 0 | P11: =LOG10(N11)*20 -> 0 | R11: =IF(F11="","",(F11-(E11*$V$71+$V$72))*100/(MAX($F$5:$F$105)*0.9)) | U11: PRNU1288 | V11: =SQRT(V14-V13)*100/(V15-V16) -> #N/A | W11: %
E12: =IF(F12="","",E11+1) | F12: =IF(G12="","",B12) | G12: =IF(SUM($H$5:H11)<1,C12,"") | H12: =IF(MAX($C$5:$C$105)=C12,1,"") -> 1 | I12: =C12^2-$C$5^2 -> 0 | J12: =IF(AND($V$40>F12,NOT(G12="")),F12,"") -> #N/A | K12: =IF(AND($V$40>F12,NOT(G12="")),I12,"") -> #N/A | L12: =IF(G12="",L11,F12*$V$6*(100/$V$5)) | M12: =IF(G12="",M11,(F12-$F$5)/G12) -> 1 | N12: =IF(G12="",M11,(F12-$F$5)/D12) -> 1 | O12: =LOG10(M12)*20 -> 0 | P12: =LOG10(N12)*20 -> 0 | R12: =IF(F12="","",(F12-(E12*$V$71+$V$72))*100/(MAX($F$5:$F$105)*0.9))
E13: =IF(F13="","",E12+1) | F13: =IF(G13="","",B13) | G13: =IF(SUM($H$5:H12)<1,C13,"") | H13: =IF(MAX($C$5:$C$105)=C13,1,"") -> 1 | I13: =C13^2-$C$5^2 -> 0 | J13: =IF(AND($V$40>F13,NOT(G13="")),F13,"") -> #N/A | K13: =IF(AND($V$40>F13,NOT(G13="")),I13,"") -> #N/A | L13: =IF(G13="",L12,F13*$V$6*(100/$V$5)) | M13: =IF(G13="",M12,(F13-$F$5)/G13) -> 1 | N13: =IF(G13="",M12,(F13-$F$5)/D13) -> 1 | O13: =LOG10(M13)*20 -> 0 | P13: =LOG10(N13)*20 -> 0 | R13: =IF(F13="","",(F13-(E13*$V$71+$V$72))*100/(MAX($F$5:$F$105)*0.9)) | U13: Sy.dark^2 | V13: =D5^2-C5^2 -> 0
E14: =IF(F14="","",E13+1) | F14: =IF(G14="","",B14) | G14: =IF(SUM($H$5:H13)<1,C14,"") | H14: =IF(MAX($C$5:$C$105)=C14,1,"") -> 1 | I14: =C14^2-$C$5^2 -> 0 | J14: =IF(AND($V$40>F14,NOT(G14="")),F14,"") -> #N/A | K14: =IF(AND($V$40>F14,NOT(G14="")),I14,"") -> #N/A | L14: =IF(G14="",L13,F14*$V$6*(100/$V$5)) | M14: =IF(G14="",M13,(F14-$F$5)/G14) -> 1 | N14: =IF(G14="",M13,(F14-$F$5)/D14) -> 1 | O14: =LOG10(M14)*20 -> 0 | P14: =LOG10(N14)*20 -> 0 | R14: =IF(F14="","",(F14-(E14*$V$71+$V$72))*100/(MAX($F$5:$F$105)*0.9)) | U14: Sy.50^2 | V14: =INDEX(D5:D105,(MATCH(MAX(F5:F105),F5:F105,0))*0.5,0)^2-INDEX(C5:C105,(MATCH(MAX(F5:F105),F5:F105,0))*0.5,0)^2 -> #N/A
E15: =IF(F15="","",E14+1) | F15: =IF(G15="","",B15) | G15: =IF(SUM($H$5:H14)<1,C15,"") | H15: =IF(MAX($C$5:$C$105)=C15,1,"") -> 1 | I15: =C15^2-$C$5^2 -> 0 | J15: =IF(AND($V$40>F15,NOT(G15="")),F15,"") -> #N/A | K15: =IF(AND($V$40>F15,NOT(G15="")),I15,"") -> #N/A | L15: =IF(G15="",L14,F15*$V$6*(100/$V$5)) | M15: =IF(G15="",M14,(F15-$F$5)/G15) -> 1 | N15: =IF(G15="",M14,(F15-$F$5)/D15) -> 1 | O15: =LOG10(M15)*20 -> 0 | P15: =LOG10(N15)*20 -> 0 | R15: =IF(F15="","",(F15-(E15*$V$71+$V$72))*100/(MAX($F$5:$F$105)*0.9)) | U15: uy.50 | V15: =INDEX(B5:B105,(MATCH(MAX(F5:F105),F5:F105,0))*0.5,0) -> #N/A
E16: =IF(F16="","",E15+1) | F16: =IF(G16="","",B16) | G16: =IF(SUM($H$5:H15)<1,C16,"") | H16: =IF(MAX($C$5:$C$105)=C16,1,"") -> 1 | I16: =C16^2-$C$5^2 -> 0 | J16: =IF(AND($V$40>F16,NOT(G16="")),F16,"") -> #N/A | K16: =IF(AND($V$40>F16,NOT(G16="")),I16,"") -> #N/A | L16: =IF(G16="",L15,F16*$V$6*(100/$V$5)) | M16: =IF(G16="",M15,(F16-$F$5)/G16) -> 1 | N16: =IF(G16="",M15,(F16-$F$5)/D16) -> 1 | O16: =LOG10(M16)*20 -> 0 | P16: =LOG10(N16)*20 -> 0 | R16: =IF(F16="","",(F16-(E16*$V$71+$V$72))*100/(MAX($F$5:$F$105)*0.9)) | U16: uy.dark | V16: =B5 -> 0
E17: =IF(F17="","",E16+1) | F17: =IF(G17="","",B17) | G17: =IF(SUM($H$5:H16)<1,C17,"") | H17: =IF(MAX($C$5:$C$105)=C17,1,"") -> 1 | I17: =C17^2-$C$5^2 -> 0 | J17: =IF(AND($V$40>F17,NOT(G17="")),F17,"") -> #N/A | K17: =IF(AND($V$40>F17,NOT(G17="")),I17,"") -> #N/A | L17: =IF(G17="",L16,F17*$V$6*(100/$V$5)) | M17: =IF(G17="",M16,(F17-$F$5)/G17) -> 1 | N17: =IF(G17="",M16,(F17-$F$5)/D17) -> 1 | O17: =LOG10(M17)*20 -> 0 | P17: =LOG10(N17)*20 -> 0 | R17: =IF(F17="","",(F17-(E17*$V$71+$V$72))*100/(MAX($F$5:$F$105)*0.9))
E18: =IF(F18="","",E17+1) | F18: =IF(G18="","",B18) | G18: =IF(SUM($H$5:H17)<1,C18,"") | H18: =IF(MAX($C$5:$C$105)=C18,1,"") -> 1 | I18: =C18^2-$C$5^2 -> 0 | J18: =IF(AND($V$40>F18,NOT(G18="")),F18,"") -> #N/A | K18: =IF(AND($V$40>F18,NOT(G18="")),I18,"") -> #N/A | L18: =IF(G18="",L17,F18*$V$6*(100/$V$5)) | M18: =IF(G18="",M17,(F18-$F$5)/G18) -> 1 | N18: =IF(G18="",M17,(F18-$F$5)/D18) -> 1 | O18: =LOG10(M18)*20 -> 0 | P18: =LOG10(N18)*20 -> 0 | R18: =IF(F18="","",(F18-(E18*$V$71+$V$72))*100/(MAX($F$5:$F$105)*0.9))
E19: =IF(F19="","",E18+1) | F19: =IF(G19="","",B19) | G19: =IF(SUM($H$5:H18)<1,C19,"") | H19: =IF(MAX($C$5:$C$105)=C19,1,"") -> 1 | I19: =C19^2-$C$5^2 -> 0 | J19: =IF(AND($V$40>F19,NOT(G19="")),F19,"") -> #N/A | K19: =IF(AND($V$40>F19,NOT(G19="")),I19,"") -> #N/A | L19: =IF(G19="",L18,F19*$V$6*(100/$V$5)) | M19: =IF(G19="",M18,(F19-$F$5)/G19) -> 1 | N19: =IF(G19="",M18,(F19-$F$5)/D19) -> 1 | O19: =LOG10(M19)*20 -> 0 | P19: =LOG10(N19)*20 -> 0 | R19: =IF(F19="","",(F19-(E19*$V$71+$V$72))*100/(MAX($F$5:$F$105)*0.9))
E20: =IF(F20="","",E19+1) | F20: =IF(G20="","",B20) | G20: =IF(SUM($H$5:H19)<1,C20,"") | H20: =IF(MAX($C$5:$C$105)=C20,1,"") -> 1 | I20: =C20^2-$C$5^2 -> 0 | J20: =IF(AND($V$40>F20,NOT(G20="")),F20,"") -> #N/A | K20: =IF(AND($V$40>F20,NOT(G20="")),I20,"") -> #N/A | L20: =IF(G20="",L19,F20*$V$6*(100/$V$5)) | M20: =IF(G20="",M19,(F20-$F$5)/G20) -> 1 | N20: =IF(G20="",M19,(F20-$F$5)/D20) -> 1 | O20: =LOG10(M20)*20 -> 0 | P20: =LOG10(N20)*20 -> 0 | R20: =IF(F20="","",(F20-(E20*$V$71+$V$72))*100/(MAX($F$5:$F$105)*0.9))
E21: =IF(F21="","",E20+1) | F21: =IF(G21="","",B21) | G21: =IF(SUM($H$5:H20)<1,C21,"") | H21: =IF(MAX($C$5:$C$105)=C21,1,"") -> 1 | I21: =C21^2-$C$5^2 -> 0 | J21: =IF(AND($V$40>F21,NOT(G21="")),F21,"") -> #N/A | K21: =IF(AND($V$40>F21,NOT(G21="")),I21,"") -> #N/A | L21: =IF(G21="",L20,F21*$V$6*(100/$V$5)) | M21: =IF(G21="",M20,(F21-$F$5)/G21) -> 1 | N21: =IF(G21="",M20,(F21-$F$5)/D21) -> 1 | O21: =LOG10(M21)*20 -> 0 | P21: =LOG10(N21)*20 -> 0 | R21: =IF(F21="","",(F21-(E21*$V$71+$V$72))*100/(MAX($F$5:$F$105)*0.9))
E22: =IF(F22="","",E21+1) | F22: =IF(G22="","",B22) | G22: =IF(SUM($H$5:H21)<1,C22,"") | H22: =IF(MAX($C$5:$C$105)=C22,1,"") -> 1 | I22: =C22^2-$C$5^2 -> 0 | J22: =IF(AND($V$40>F22,NOT(G22="")),F22,"") -> #N/A | K22: =IF(AND($V$40>F22,NOT(G22="")),I22,"") -> #N/A | L22: =IF(G22="",L21,F22*$V$6*(100/$V$5)) | M22: =IF(G22="",M21,(F22-$F$5)/G22) -> 1 | N22: =IF(G22="",M21,(F22-$F$5)/D22) -> 1 | O22: =LOG10(M22)*20 -> 0 | P22: =LOG10(N22)*20 -> 0 | R22: =IF(F22="","",(F22-(E22*$V$71+$V$72))*100/(MAX($F$5:$F$105)*0.9))
E23: =IF(F23="","",E22+1) | F23: =IF(G23="","",B23) | G23: =IF(SUM($H$5:H22)<1,C23,"") | H23: =IF(MAX($C$5:$C$105)=C23,1,"") -> 1 | I23: =C23^2-$C$5^2 -> 0 | J23: =IF(AND($V$40>F23,NOT(G23="")),F23,"") -> #N/A | K23: =IF(AND($V$40>F23,NOT(G23="")),I23,"") -> #N/A | L23: =IF(G23="",L22,F23*$V$6*(100/$V$5)) | M23: =IF(G23="",M22,(F23-$F$5)/G23) -> 1 | N23: =IF(G23="",M22,(F23-$F$5)/D23) -> 1 | O23: =LOG10(M23)*20 -> 0 | P23: =LOG10(N23)*20 -> 0 | R23: =IF(F23="","",(F23-(E23*$V$71+$V$72))*100/(MAX($F$5:$F$105)*0.9))
E24: =IF(F24="","",E23+1) | F24: =IF(G24="","",B24) | G24: =IF(SUM($H$5:H23)<1,C24,"") | H24: =IF(MAX($C$5:$C$105)=C24,1,"") -> 1 | I24: =C24^2-$C$5^2 -> 0 | J24: =IF(AND($V$40>F24,NOT(G24="")),F24,"") -> #N/A | K24: =IF(AND($V$40>F24,NOT(G24="")),I24,"") -> #N/A | L24: =IF(G24="",L23,F24*$V$6*(100/$V$5)) | M24: =IF(G24="",M23,(F24-$F$5)/G24) -> 1 | R24: =IF(F24="","",(F24-(E24*$V$71+$V$72))*100/(MAX($F$5:$F$105)*0.9)) | U24: 항목 | V24: photon | W24: ratio
E25: =IF(F25="","",E24+1) | F25: =IF(G25="","",B25) | G25: =IF(SUM($H$5:H24)<1,C25,"") | H25: =IF(MAX($C$5:$C$105)=C25,1,"") -> 1 | I25: =C25^2-$C$5^2 -> 0 | J25: =IF(AND($V$40>F25,NOT(G25="")),F25,"") -> #N/A | K25: =IF(AND($V$40>F25,NOT(G25="")),I25,"") -> #N/A | L25: =IF(G25="",L24,F25*$V$6*(100/$V$5)) | M25: =IF(G25="",M24,(F25-$F$5)/G25) -> 1 | R25: =IF(F25="","",(F25-(E25*$V$71+$V$72))*100/(MAX($F$5:$F$105)*0.9)) | U25: SNR 1 | V25: =MIN(L4:L104) -> 0 | W25: =MIN(M4:M104) -> 1
E26: =IF(F26="","",E25+1) | F26: =IF(G26="","",B26) | G26: =IF(SUM($H$5:H25)<1,C26,"") | H26: =IF(MAX($C$5:$C$105)=C26,1,"") -> 1 | I26: =C26^2-$C$5^2 -> 0 | J26: =IF(AND($V$40>F26,NOT(G26="")),F26,"") -> #N/A | K26: =IF(AND($V$40>F26,NOT(G26="")),I26,"") -> #N/A | L26: =IF(G26="",L25,F26*$V$6*(100/$V$5)) | M26: =IF(G26="",M25,(F26-$F$5)/G26) -> 1 | R26: =IF(F26="","",(F26-(E26*$V$71+$V$72))*100/(MAX($F$5:$F$105)*0.9)) | U26: SNR MAX(Saturation) | V26: =MAX(L6:L105) -> 0 | W26: =MAX(M6:M105) -> 1
E27: =IF(F27="","",E26+1) | F27: =IF(G27="","",B27) | G27: =IF(SUM($H$5:H26)<1,C27,"") | H27: =IF(MAX($C$5:$C$105)=C27,1,"") -> 1 | I27: =C27^2-$C$5^2 -> 0 | J27: =IF(AND($V$40>F27,NOT(G27="")),F27,"") -> #N/A | K27: =IF(AND($V$40>F27,NOT(G27="")),I27,"") -> #N/A | L27: =IF(G27="",L26,F27*$V$6*(100/$V$5)) | M27: =IF(G27="",M26,(F27-$F$5)/G27) -> 1 | R27: =IF(F27="","",(F27-(E27*$V$71+$V$72))*100/(MAX($F$5:$F$105)*0.9)) | U27: theor.limit | V27: 1 | W27: =SQRT(V27) -> 1
E28: =IF(F28="","",E27+1) | F28: =IF(G28="","",B28) | G28: =IF(SUM($H$5:H27)<1,C28,"") | H28: =IF(MAX($C$5:$C$105)=C28,1,"") -> 1 | I28: =C28^2-$C$5^2 -> 0 | J28: =IF(AND($V$40>F28,NOT(G28="")),F28,"") -> #N/A | K28: =IF(AND($V$40>F28,NOT(G28="")),I28,"") -> #N/A | L28: =IF(G28="",L27,F28*$V$6*(100/$V$5)) | M28: =IF(G28="",M27,(F28-$F$5)/G28) -> 1 | R28: =IF(F28="","",(F28-(E28*$V$71+$V$72))*100/(MAX($F$5:$F$105)*0.9)) | V28: 1000000 | W28: =SQRT(V28) -> 1000
E29: =IF(F29="","",E28+1) | F29: =IF(G29="","",B29) | G29: =IF(SUM($H$5:H28)<1,C29,"") | H29: =IF(MAX($C$5:$C$105)=C29,1,"") -> 1 | I29: =C29^2-$C$5^2 -> 0 | J29: =IF(AND($V$40>F29,NOT(G29="")),F29,"") -> #N/A | K29: =IF(AND($V$40>F29,NOT(G29="")),I29,"") -> #N/A | L29: =IF(G29="",L28,F29*$V$6*(100/$V$5)) | M29: =IF(G29="",M28,(F29-$F$5)/G29) -> 1 | R29: =IF(F29="","",(F29-(E29*$V$71+$V$72))*100/(MAX($F$5:$F$105)*0.9))
E30: =IF(F30="","",E29+1) | F30: =IF(G30="","",B30) | G30: =IF(SUM($H$5:H29)<1,C30,"") | H30: =IF(MAX($C$5:$C$105)=C30,1,"") -> 1 | I30: =C30^2-$C$5^2 -> 0 | J30: =IF(AND($V$40>F30,NOT(G30="")),F30,"") -> #N/A | K30: =IF(AND($V$40>F30,NOT(G30="")),I30,"") -> #N/A | L30: =IF(G30="",L29,F30*$V$6*(100/$V$5)) | M30: =IF(G30="",M29,(F30-$F$5)/G30) -> 1 | R30: =IF(F30="","",(F30-(E30*$V$71+$V$72))*100/(MAX($F$5:$F$105)*0.9))
E31: =IF(F31="","",E30+1) | F31: =IF(G31="","",B31) | G31: =IF(SUM($H$5:H30)<1,C31,"") | H31: =IF(MAX($C$5:$C$105)=C31,1,"") -> 1 | I31: =C31^2-$C$5^2 -> 0 | J31: =IF(AND($V$40>F31,NOT(G31="")),F31,"") -> #N/A | K31: =IF(AND($V$40>F31,NOT(G31="")),I31,"") -> #N/A | L31: =IF(G31="",L30,F31*$V$6*(100/$V$5)) | M31: =IF(G31="",M30,(F31-$F$5)/G31) -> 1 | R31: =IF(F31="","",(F31-(E31*$V$71+$V$72))*100/(MAX($F$5:$F$105)*0.9))
E32: =IF(F32="","",E31+1) | F32: =IF(G32="","",B32) | G32: =IF(SUM($H$5:H31)<1,C32,"") | H32: =IF(MAX($C$5:$C$105)=C32,1,"") -> 1 | I32: =C32^2-$C$5^2 -> 0 | J32: =IF(AND($V$40>F32,NOT(G32="")),F32,"") -> #N/A | K32: =IF(AND($V$40>F32,NOT(G32="")),I32,"") -> #N/A | L32: =IF(G32="",L31,F32*$V$6*(100/$V$5)) | M32: =IF(G32="",M31,(F32-$F$5)/G32) -> 1 | R32: =IF(F32="","",(F32-(E32*$V$71+$V$72))*100/(MAX($F$5:$F$105)*0.9))
E33: =IF(F33="","",E32+1) | F33: =IF(G33="","",B33) | G33: =IF(SUM($H$5:H32)<1,C33,"") | H33: =IF(MAX($C$5:$C$105)=C33,1,"") -> 1 | I33: =C33^2-$C$5^2 -> 0 | J33: =IF(AND($V$40>F33,NOT(G33="")),F33,"") -> #N/A | K33: =IF(AND($V$40>F33,NOT(G33="")),I33,"") -> #N/A | L33: =IF(G33="",L32,F33*$V$6*(100/$V$5)) | M33: =IF(G33="",M32,(F33-$F$5)/G33) -> 1 | R33: =IF(F33="","",(F33-(E33*$V$71+$V$72))*100/(MAX($F$5:$F$105)*0.9))
E34: =IF(F34="","",E33+1) | F34: =IF(G34="","",B34) | G34: =IF(SUM($H$5:H33)<1,C34,"") | H34: =IF(MAX($C$5:$C$105)=C34,1,"") -> 1 | I34: =C34^2-$C$5^2 -> 0 | J34: =IF(AND($V$40>F34,NOT(G34="")),F34,"") -> #N/A | K34: =IF(AND($V$40>F34,NOT(G34="")),I34,"") -> #N/A | L34: =IF(G34="",L33,F34*$V$6*(100/$V$5)) | M34: =IF(G34="",M33,(F34-$F$5)/G34) -> 1 | R34: =IF(F34="","",(F34-(E34*$V$71+$V$72))*100/(MAX($F$5:$F$105)*0.9))
E35: =IF(F35="","",E34+1) | F35: =IF(G35="","",B35) | G35: =IF(SUM($H$5:H34)<1,C35,"") | H35: =IF(MAX($C$5:$C$105)=C35,1,"") -> 1 | I35: =C35^2-$C$5^2 -> 0 | J35: =IF(AND($V$40>F35,NOT(G35="")),F35,"") -> #N/A | K35: =IF(AND($V$40>F35,NOT(G35="")),I35,"") -> #N/A | L35: =IF(G35="",L34,F35*$V$6*(100/$V$5)) | M35: =IF(G35="",M34,(F35-$F$5)/G35) -> 1 | R35: =IF(F35="","",(F35-(E35*$V$71+$V$72))*100/(MAX($F$5:$F$105)*0.9))
E36: =IF(F36="","",E35+1) | F36: =IF(G36="","",B36) | G36: =IF(SUM($H$5:H35)<1,C36,"") | H36: =IF(MAX($C$5:$C$105)=C36,1,"") -> 1 | I36: =C36^2-$C$5^2 -> 0 | J36: =IF(AND($V$40>F36,NOT(G36="")),F36,"") -> #N/A | K36: =IF(AND($V$40>F36,NOT(G36="")),I36,"") -> #N/A | L36: =IF(G36="",L35,F36*$V$6*(100/$V$5)) | M36: =IF(G36="",M35,(F36-$F$5)/G36) -> 1 | R36: =IF(F36="","",(F36-(E36*$V$71+$V$72))*100/(MAX($F$5:$F$105)*0.9))
E37: =IF(F37="","",E36+1) | F37: =IF(G37="","",B37) | G37: =IF(SUM($H$5:H36)<1,C37,"") | H37: =IF(MAX($C$5:$C$105)=C37,1,"") -> 1 | I37: =C37^2-$C$5^2 -> 0 | J37: =IF(AND($V$40>F37,NOT(G37="")),F37,"") -> #N/A | K37: =IF(AND($V$40>F37,NOT(G37="")),I37,"") -> #N/A | L37: =IF(G37="",L36,F37*$V$6*(100/$V$5)) | M37: =IF(G37="",M36,(F37-$F$5)/G37) -> 1 | R37: =IF(F37="","",(F37-(E37*$V$71+$V$72))*100/(MAX($F$5:$F$105)*0.9))
E38: =IF(F38="","",E37+1) | F38: =IF(G38="","",B38) | G38: =IF(SUM($H$5:H37)<1,C38,"") | H38: =IF(MAX($C$5:$C$105)=C38,1,"") -> 1 | I38: =C38^2-$C$5^2 -> 0 | J38: =IF(AND($V$40>F38,NOT(G38="")),F38,"") -> #N/A | K38: =IF(AND($V$40>F38,NOT(G38="")),I38,"") -> #N/A | L38: =IF(G38="",L37,F38*$V$6*(100/$V$5)) | M38: =IF(G38="",M37,(F38-$F$5)/G38) -> 1 | R38: =IF(F38="","",(F38-(E38*$V$71+$V$72))*100/(MAX($F$5:$F$105)*0.9)) | U38: 항목 | V38: X | W38: Y
E39: =IF(F39="","",E38+1) | F39: =IF(G39="","",B39) | G39: =IF(SUM($H$5:H38)<1,C39,"") | H39: =IF(MAX($C$5:$C$105)=C39,1,"") -> 1 | I39: =C39^2-$C$5^2 -> 0 | J39: =IF(AND($V$40>F39,NOT(G39="")),F39,"") -> #N/A | K39: =IF(AND($V$40>F39,NOT(G39="")),I39,"") -> #N/A | L39: =IF(G39="",L38,F39*$V$6*(100/$V$5)) | M39: =IF(G39="",M38,(F39-$F$5)/G39) -> 1 | R39: =IF(F39="","",(F39-(E39*$V$71+$V$72))*100/(MAX($F$5:$F$105)*0.9)) | U39: fit Line | V39: 0 | W39: =SQRT(V39) -> 0
E40: =IF(F40="","",E39+1) | F40: =IF(G40="","",B40) | G40: =IF(SUM($H$5:H39)<1,C40,"") | H40: =IF(MAX($C$5:$C$105)=C40,1,"") -> 1 | I40: =C40^2-$C$5^2 -> 0 | J40: =IF(AND($V$40>F40,NOT(G40="")),F40,"") -> #N/A | K40: =IF(AND($V$40>F40,NOT(G40="")),I40,"") -> #N/A | L40: =IF(G40="",L39,F40*$V$6*(100/$V$5)) | M40: =IF(G40="",M39,(F40-$F$5)/G40) -> 1 | R40: =IF(F40="","",(F40-(E40*$V$71+$V$72))*100/(MAX($F$5:$F$105)*0.9)) | V40: =INDEX(F5:F105,(MATCH(MAX(F5:F105),F5:F105,0))*0.7,0) -> #N/A | W40: =V40/V6 -> #N/A
E41: =IF(F41="","",E40+1) | F41: =IF(G41="","",B41) | G41: =IF(SUM($H$5:H40)<1,C41,"") | H41: =IF(MAX($C$5:$C$105)=C41,1,"") -> 1 | I41: =C41^2-$C$5^2 -> 0 | J41: =IF(AND($V$40>F41,NOT(G41="")),F41,"") -> #N/A | K41: =IF(AND($V$40>F41,NOT(G41="")),I41,"") -> #N/A | L41: =IF(G41="",L40,F41*$V$6*(100/$V$5)) | M41: =IF(G41="",M40,(F41-$F$5)/G41) -> 1 | R41: =IF(F41="","",(F41-(E41*$V$71+$V$72))*100/(MAX($F$5:$F$105)*0.9)) | U41: Saturation Line | V41: =MAX(F5:F103) -> 0 | W41: =(MAX(C5:C103))^2 -> 0
...

Sheet Linearity Data(Exposure)
A2: Input Data | E2: Output
A3: Exp/ Light Level | B3: Gray Value (uy-Uy.dark) | C3: Temporal STD | D3: Total STD | E3: Index | F3: Gray Value (uy-Uy.dark) | G3: STD | H3: STD CHK | I3: Variance gray | J3: Variance Fit | L3: photons | M3: SNR(linear) | R3: Linearity Error(%)
H4: STD CHK | J4: GrayValue | K4: Variance slop | O4: SNR Db
A5: 0.1 | B5: 1.5 | E5: 0 | F5: =IF(G5="","",B5) | G5: =IF(SUM($H4:H$5)<1,C5,"") | H5: =IF(MAX($C$5:$C$105)=C5,1,"") -> 1 | I5: =C5^2-$C$5^2 -> 0 | J5: =IF(AND($V$40>F5,NOT(G5="")),F5,"") -> #N/A | K5: =IF(AND($V$40>F5,NOT(G5="")),I5,"") -> #N/A | L5: =IF(G5="","",G5*$V$6*(100/$V$5)) | M5: 1 | N5: 1 | O5: =LOG10(M5)*20 -> 0 | P5: 0 | Q5: =LOG10(M5)*20 -> 0 | R5: =IF(F5="","",(F5-(E5*$V$71+$V$72))*100/(MAX($F$5:$F$105)*0.9)) | U5: Quamtum Eppiciency | V5: 88.4
A6: 0.2 | B6: 1.8 | E6: =IF(F6="","",E5+1) | F6: =IF(G6="","",B6) | G6: =IF(SUM($H5:H$5)<1,C6,"") | H6: =IF(MAX($C$5:$C$105)=C6,1,"") -> 1 | I6: =C6^2-$C$5^2 -> 0 | J6: =IF(AND($V$40>F6,NOT(G6="")),F6,"") -> #N/A | K6: =IF(AND($V$40>F6,NOT(G6="")),I6,"") -> #N/A | L6: =IF(G6="",L5,F6*$V$6*(100/$V$5)) | M6: =IF(G6="",M5,(F6-$F$5)/G6) -> 1 | N6: =IF(G6="",M5,(F6-$F$5)/D6) -> 1 | O6: =LOG10(M6)*20 -> 0 | P6: =LOG10(N6)*20 -> 0 | R6: =IF(F6="","",(F6-(E6*$V$71+$V$72))*100/(MAX($F$5:$F$105)*0.9)) | U6: System Gain | V6: =1/((MATCH(MAX(K5:K105),K5:K105)*SUMPRODUCT(J5:J105,K5:K105)-SUM(J5:J105)*SUM(K5:K105))/(MATCH(MAX(K5:K105),K5:K105)*SUMSQ(J5:J105) - SUM(J5:J105)^2)) -> #N/A
A7: 0.3 | B7: 2.1 | E7: =IF(F7="","",E6+1) | F7: =IF(G7="","",B7) | G7: =IF(SUM($H$5:H6)<1,C7,"") | H7: =IF(MAX($C$5:$C$105)=C7,1,"") -> 1 | I7: =C7^2-$C$5^2 -> 0 | J7: =IF(AND($V$40>F7,NOT(G7="")),F7,"") -> #N/A | K7: =IF(AND($V$40>F7,NOT(G7="")),I7,"") -> #N/A | L7: =IF(G7="",L6,F7*$V$6*(100/$V$5)) | M7: =IF(G7="",M6,(F7-$F$5)/G7) -> 1 | N7: =IF(G7="",M6,(F7-$F$5)/D7) -> 1 | O7: =LOG10(M7)*20 -> 0 | P7: =LOG10(N7)*20 -> 0 | R7: =IF(F7="","",(F7-(E7*$V$71+$V$72))*100/(MAX($F$5:$F$105)*0.9))
A8: 0.4 | B8: 2.4 | E8: =IF(F8="","",E7+1) | F8: =IF(G8="","",B8) | G8: =IF(SUM($H$5:H7)<1,C8,"") | H8: =IF(MAX($C$5:$C$105)=C8,1,"") -> 1 | I8: =C8^2-$C$5^2 -> 0 | J8: =IF(AND($V$40>F8,NOT(G8="")),F8,"") -> #N/A | K8: =IF(AND($V$40>F8,NOT(G8="")),I8,"") -> #N/A | L8: =IF(G8="",L7,F8*$V$6*(100/$V$5)) | M8: =IF(G8="",M7,(F8-$F$5)/G8) -> 1 | N8: =IF(G8="",M7,(F8-$F$5)/D8) -> 1 | O8: =LOG10(M8)*20 -> 0 | P8: =LOG10(N8)*20 -> 0 | R8: =IF(F8="","",(F8-(E8*$V$71+$V$72))*100/(MAX($F$5:$F$105)*0.9))
A9: 0.5 | B9: 2.7 | E9: =IF(F9="","",E8+1) | F9: =IF(G9="","",B9) | G9: =IF(SUM($H$5:H8)<1,C9,"") | H9: =IF(MAX($C$5:$C$105)=C9,1,"") -> 1 | I9: =C9^2-$C$5^2 -> 0 | J9: =IF(AND($V$40>F9,NOT(G9="")),F9,"") -> #N/A | K9: =IF(AND($V$40>F9,NOT(G9="")),I9,"") -> #N/A | L9: =IF(G9="",L8,F9*$V$6*(100/$V$5)) | M9: =IF(G9="",M8,(F9-$F$5)/G9) -> 1 | N9: =IF(G9="",M8,(F9-$F$5)/D9) -> 1 | O9: =LOG10(M9)*20 -> 0 | P9: =LOG10(N9)*20 -> 0 | R9: =IF(F9="","",(F9-(E9*$V$71+$V$72))*100/(MAX($F$5:$F$105)*0.9))
A10: 0.6 | B10: 3 | E10: =IF(F10="","",E9+1) | F10: =IF(G10="","",B10) | G10: =IF(SUM($H$5:H9)<1,C10,"") | H10: =IF(MAX($C$5:$C$105)=C10,1,"") -> 1 | I10: =C10^2-$C$5^2 -> 0 | J10: =IF(AND($V$40>F10,NOT(G10="")),F10,"") -> #N/A | K10: =IF(AND($V$40>F10,NOT(G10="")),I10,"") -> #N/A | L10: =IF(G10="",L9,F10*$V$6*(100/$V$5)) | M10: =IF(G10="",M9,(F10-$F$5)/G10) -> 1 | N10: =IF(G10="",M9,(F10-$F$5)/D10) -> 1 | O10: =LOG10(M10)*20 -> 0 | P10: =LOG10(N10)*20 -> 0 | R10: =IF(F10="","",(F10-(E10*$V$71+$V$72))*100/(MAX($F$5:$F$105)*0.9)) | U10: DSNU1288 | V10: =SQRT(V13)*V6 -> #N/A | W10: e-
A11: 0.7 | B11: 3.3 | E11: =IF(F11="","",E10+1) | F11: =IF(G11="","",B11) | G11: =IF(SUM($H$5:H10)<1,C11,"") | H11: =IF(MAX($C$5:$C$105)=C11,1,"") -> 1 | I11: =C11^2-$C$5^2 -> 0 | J11: =IF(AND($V$40>F11,NOT(G11="")),F11,"") -> #N/A | K11: =IF(AND($V$40>F11,NOT(G11="")),I11,"") -> #N/A | L11: =IF(G11="",L10,F11*$V$6*(100/$V$5)) | M11: =IF(G11="",M10,(F11-$F$5)/G11) -> 1 | N11: =IF(G11="",M10,(F11-$F$5)/D11) -> 1 | O11: =LOG10(M11)*20 -> 0 | P11: =LOG10(N11)*20 -> 0 | R11: =IF(F11="","",(F11-(E11*$V$71+$V$72))*100/(MAX($F$5:$F$105)*0.9)) | U11: PRNU1288 | V11: =SQRT(V14-V13)*100/(V15-V16) -> #N/A | W11: %
A12: 0.8 | B12: 3.6 | E12: =IF(F12="","",E11+1) | F12: =IF(G12="","",B12) | G12: =IF(SUM($H$5:H11)<1,C12,"") | H12: =IF(MAX($C$5:$C$105)=C12,1,"") -> 1 | I12: =C12^2-$C$5^2 -> 0 | J12: =IF(AND($V$40>F12,NOT(G12="")),F12,"") -> #N/A | K12: =IF(AND($V$40>F12,NOT(G12="")),I12,"") -> #N/A | L12: =IF(G12="",L11,F12*$V$6*(100/$V$5)) | M12: =IF(G12="",M11,(F12-$F$5)/G12) -> 1 | N12: =IF(G12="",M11,(F12-$F$5)/D12) -> 1 | O12: =LOG10(M12)*20 -> 0 | P12: =LOG10(N12)*20 -> 0 | R12: =IF(F12="","",(F12-(E12*$V$71+$V$72))*100/(MAX($F$5:$F$105)*0.9))
A13: 0.9 | B13: 3.9 | E13: =IF(F13="","",E12+1) | F13: =IF(G13="","",B13) | G13: =IF(SUM($H$5:H12)<1,C13,"") | H13: =IF(MAX($C$5:$C$105)=C13,1,"") -> 1 | I13: =C13^2-$C$5^2 -> 0 | J13: =IF(AND($V$40>F13,NOT(G13="")),F13,"") -> #N/A | K13: =IF(AND($V$40>F13,NOT(G13="")),I13,"") -> #N/A | L13: =IF(G13="",L12,F13*$V$6*(100/$V$5)) | M13: =IF(G13="",M12,(F13-$F$5)/G13) -> 1 | N13: =IF(G13="",M12,(F13-$F$5)/D13) -> 1 | O13: =LOG10(M13)*20 -> 0 | P13: =LOG10(N13)*20 -> 0 | R13: =IF(F13="","",(F13-(E13*$V$71+$V$72))*100/(MAX($F$5:$F$105)*0.9)) | U13: Sy.dark^2 | V13: =D5^2-C5^2 -> 0
A14: 1 | B14: 4.2 | E14: =IF(F14="","",E13+1) | F14: =IF(G14="","",B14) | G14: =IF(SUM($H$5:H13)<1,C14,"") | H14: =IF(MAX($C$5:$C$105)=C14,1,"") -> 1 | I14: =C14^2-$C$5^2 -> 0 | J14: =IF(AND($V$40>F14,NOT(G14="")),F14,"") -> #N/A | K14: =IF(AND($V$40>F14,NOT(G14="")),I14,"") -> #N/A | L14: =IF(G14="",L13,F14*$V$6*(100/$V$5)) | M14: =IF(G14="",M13,(F14-$F$5)/G14) -> 1 | N14: =IF(G14="",M13,(F14-$F$5)/D14) -> 1 | O14: =LOG10(M14)*20 -> 0 | P14: =LOG10(N14)*20 -> 0 | R14: =IF(F14="","",(F14-(E14*$V$71+$V$72))*100/(MAX($F$5:$F$105)*0.9)) | U14: Sy.50^2 | V14: =INDEX(D5:D105,(MATCH(MAX(F5:F105),F5:F105,0))*0.5,0)^2-INDEX(C5:C105,(MATCH(MAX(F5:F105),F5:F105,0))*0.5,0)^2 -> #N/A
E15: =IF(F15="","",E14+1) | F15: =IF(G15="","",B15) | G15: =IF(SUM($H$5:H14)<1,C15,"") | H15: =IF(MAX($C$5:$C$105)=C15,1,"") -> 1 | I15: =C15^2-$C$5^2 -> 0 | J15: =IF(AND($V$40>F15,NOT(G15="")),F15,"") -> #N/A | K15: =IF(AND($V$40>F15,NOT(G15="")),I15,"") -> #N/A | L15: =IF(G15="",L14,F15*$V$6*(100/$V$5)) | M15: =IF(G15="",M14,(F15-$F$5)/G15) -> 1 | N15: =IF(G15="",M14,(F15-$F$5)/D15) -> 1 | O15: =LOG10(M15)*20 -> 0 | P15: =LOG10(N15)*20 -> 0 | R15: =IF(F15="","",(F15-(E15*$V$71+$V$72))*100/(MAX($F$5:$F$105)*0.9)) | U15: uy.50 | V15: =INDEX(B5:B105,(MATCH(MAX(F5:F105),F5:F105,0))*0.5,0) -> #N/A
E16: =IF(F16="","",E15+1) | F16: =IF(G16="","",B16) | G16: =IF(SUM($H$5:H15)<1,C16,"") | H16: =IF(MAX($C$5:$C$105)=C16,1,"") -> 1 | I16: =C16^2-$C$5^2 -> 0 | J16: =IF(AND($V$40>F16,NOT(G16="")),F16,"") -> #N/A | K16: =IF(AND($V$40>F16,NOT(G16="")),I16,"") -> #N/A | L16: =IF(G16="",L15,F16*$V$6*(100/$V$5)) | M16: =IF(G16="",M15,(F16-$F$5)/G16) -> 1 | N16: =IF(G16="",M15,(F16-$F$5)/D16) -> 1 | O16: =LOG10(M16)*20 -> 0 | P16: =LOG10(N16)*20 -> 0 | R16: =IF(F16="","",(F16-(E16*$V$71+$V$72))*100/(MAX($F$5:$F$105)*0.9)) | U16: uy.dark | V16: =B5 -> 1.5
E17: =IF(F17="","",E16+1) | F17: =IF(G17="","",B17) | G17: =IF(SUM($H$5:H16)<1,C17,"") | H17: =IF(MAX($C$5:$C$105)=C17,1,"") -> 1 | I17: =C17^2-$C$5^2 -> 0 | J17: =IF(AND($V$40>F17,NOT(G17="")),F17,"") -> #N/A | K17: =IF(AND($V$40>F17,NOT(G17="")),I17,"") -> #N/A | L17: =IF(G17="",L16,F17*$V$6*(100/$V$5)) | M17: =IF(G17="",M16,(F17-$F$5)/G17) -> 1 | N17: =IF(G17="",M16,(F17-$F$5)/D17) -> 1 | O17: =LOG10(M17)*20 -> 0 | P17: =LOG10(N17)*20 -> 0 | R17: =IF(F17="","",(F17-(E17*$V$71+$V$72))*100/(MAX($F$5:$F$105)*0.9)) | U17: Dark Current Slope | V17: =((MATCH(MAX(B5:B105),B5:B105)*SUMPRODUCT(A5:A105,B5:B105)-SUM(A5:A105)*SUM(B5:B105))/(MATCH(MAX(B5:B105),B5:B105)*SUMSQ(A5:A105) - SUM(A5:A105)^2)) -> 3
E18: =IF(F18="","",E17+1) | F18: =IF(G18="","",B18) | G18: =IF(SUM($H$5:H17)<1,C18,"") | H18: =IF(MAX($C$5:$C$105)=C18,1,"") -> 1 | I18: =C18^2-$C$5^2 -> 0 | J18: =IF(AND($V$40>F18,NOT(G18="")),F18,"") -> #N/A | K18: =IF(AND($V$40>F18,NOT(G18="")),I18,"") -> #N/A | L18: =IF(G18="",L17,F18*$V$6*(100/$V$5)) | M18: =IF(G18="",M17,(F18-$F$5)/G18) -> 1 | N18: =IF(G18="",M17,(F18-$F$5)/D18) -> 1 | O18: =LOG10(M18)*20 -> 0 | P18: =LOG10(N18)*20 -> 0 | R18: =IF(F18="","",(F18-(E18*$V$71+$V$72))*100/(MAX($F$5:$F$105)*0.9)) | U18: Dark Current | V18: =V17*'Linearity Data'!V6 -> #N/A | W18: DN/s
E19: =IF(F19="","",E18+1) | F19: =IF(G19="","",B19) | G19: =IF(SUM($H$5:H18)<1,C19,"") | H19: =IF(MAX($C$5:$C$105)=C19,1,"") -> 1 | I19: =C19^2-$C$5^2 -> 0 | J19: =IF(AND($V$40>F19,NOT(G19="")),F19,"") -> #N/A | K19: =IF(AND($V$40>F19,NOT(G19="")),I19,"") -> #N/A | L19: =IF(G19="",L18,F19*$V$6*(100/$V$5)) | M19: =IF(G19="",M18,(F19-$F$5)/G19) -> 1 | N19: =IF(G19="",M18,(F19-$F$5)/D19) -> 1 | O19: =LOG10(M19)*20 -> 0 | P19: =LOG10(N19)*20 -> 0 | R19: =IF(F19="","",(F19-(E19*$V$71+$V$72))*100/(MAX($F$5:$F$105)*0.9))
E20: =IF(F20="","",E19+1) | F20: =IF(G20="","",B20) | G20: =IF(SUM($H$5:H19)<1,C20,"") | H20: =IF(MAX($C$5:$C$105)=C20,1,"") -> 1 | I20: =C20^2-$C$5^2 -> 0 | J20: =IF(AND($V$40>F20,NOT(G20="")),F20,"") -> #N/A | K20: =IF(AND($V$40>F20,NOT(G20="")),I20,"") -> #N/A | L20: =IF(G20="",L19,F20*$V$6*(100/$V$5)) | M20: =IF(G20="",M19,(F20-$F$5)/G20) -> 1 | N20: =IF(G20="",M19,(F20-$F$5)/D20) -> 1 | O20: =LOG10(M20)*20 -> 0 | P20: =LOG10(N20)*20 -> 0 | R20: =IF(F20="","",(F20-(E20*$V$71+$V$72))*100/(MAX($F$5:$F$105)*0.9))
E21: =IF(F21="","",E20+1) | F21: =IF(G21="","",B21) | G21: =IF(SUM($H$5:H20)<1,C21,"") | H21: =IF(MAX($C$5:$C$105)=C21,1,"") -> 1 | I21: =C21^2-$C$5^2 -> 0 | J21: =IF(AND($V$40>F21,NOT(G21="")),F21,"") -> #N/A | K21: =IF(AND($V$40>F21,NOT(G21="")),I21,"") -> #N/A | L21: =IF(G21="",L20,F21*$V$6*(100/$V$5)) | M21: =IF(G21="",M20,(F21-$F$5)/G21) -> 1 | N21: =IF(G21="",M20,(F21-$F$5)/D21) -> 1 | O21: =LOG10(M21)*20 -> 0 | P21: =LOG10(N21)*20 -> 0 | R21: =IF(F21="","",(F21-(E21*$V$71+$V$72))*100/(MAX($F$5:$F$105)*0.9))
E22: =IF(F22="","",E21+1) | F22: =IF(G22="","",B22) | G22: =IF(SUM($H$5:H21)<1,C22,"") | H22: =IF(MAX($C$5:$C$105)=C22,1,"") -> 1 | I22: =C22^2-$C$5^2 -> 0 | J22: =IF(AND($V$40>F22,NOT(G22="")),F22,"") -> #N/A | K22: =IF(AND($V$40>F22,NOT(G22="")),I22,"") -> #N/A | L22: =IF(G22="",L21,F22*$V$6*(100/$V$5)) | M22: =IF(G22="",M21,(F22-$F$5)/G22) -> 1 | N22: =IF(G22="",M21,(F22-$F$5)/D22) -> 1 | O22: =LOG10(M22)*20 -> 0 | P22: =LOG10(N22)*20 -> 0 | R22: =IF(F22="","",(F22-(E22*$V$71+$V$72))*100/(MAX($F$5:$F$105)*0.9))
E23: =IF(F23="","",E22+1) | F23: =IF(G23="","",B23) | G23: =IF(SUM($H$5:H22)<1,C23,"") | H23: =IF(MAX($C$5:$C$105)=C23,1,"") -> 1 | I23: =C23^2-$C$5^2 -> 0 | J23: =IF(AND($V$40>F23,NOT(G23="")),F23,"") -> #N/A | K23: =IF(AND($V$40>F23,NOT(G23="")),I23,"") -> #N/A | L23: =IF(G23="",L22,F23*$V$6*(100/$V$5)) | M23: =IF(G23="",M22,(F23-$F$5)/G23) -> 1 | N23: =IF(G23="",M22,(F23-$F$5)/D23) -> 1 | O23: =LOG10(M23)*20 -> 0 | P23: =LOG10(N23)*20 -> 0 | R23: =IF(F23="","",(F23-(E23*$V$71+$V$72))*100/(MAX($F$5:$F$105)*0.9))
E24: =IF(F24="","",E23+1) | F24: =IF(G24="","",B24) | G24: =IF(SUM($H$5:H23)<1,C24,"") | H24: =IF(MAX($C$5:$C$105)=C24,1,"") -> 1 | I24: =C24^2-$C$5^2 -> 0 | J24: =IF(AND($V$40>F24,NOT(G24="")),F24,"") -> #N/A | K24: =IF(AND($V$40>F24,NOT(G24="")),I24,"") -> #N/A | L24: =IF(G24="",L23,F24*$V$6*(100/$V$5)) | M24: =IF(G24="",M23,(F24-$F$5)/G24) -> 1 | R24: =IF(F24="","",(F24-(E24*$V$71+$V$72))*100/(MAX($F$5:$F$105)*0.9)) | U24: 항목 | V24: photon | W24: ratio
E25: =IF(F25="","",E24+1) | F25: =IF(G25="","",B25) | G25: =IF(SUM($H$5:H24)<1,C25,"") | H25: =IF(MAX($C$5:$C$105)=C25,1,"") -> 1 | I25: =C25^2-$C$5^2 -> 0 | J25: =IF(AND($V$40>F25,NOT(G25="")),F25,"") -> #N/A | K25: =IF(AND($V$40>F25,NOT(G25="")),I25,"") -> #N/A | L25: =IF(G25="",L24,F25*$V$6*(100/$V$5)) | M25: =IF(G25="",M24,(F25-$F$5)/G25) -> 1 | R25: =IF(F25="","",(F25-(E25*$V$71+$V$72))*100/(MAX($F$5:$F$105)*0.9)) | U25: SNR 1 | V25: =MIN(L4:L104) -> 0 | W25: =MIN(M4:M104) -> 1
E26: =IF(F26="","",E25+1) | F26: =IF(G26="","",B26) | G26: =IF(SUM($H$5:H25)<1,C26,"") | H26: =IF(MAX($C$5:$C$105)=C26,1,"") -> 1 | I26: =C26^2-$C$5^2 -> 0 | J26: =IF(AND($V$40>F26,NOT(G26="")),F26,"") -> #N/A | K26: =IF(AND($V$40>F26,NOT(G26="")),I26,"") -> #N/A | L26: =IF(G26="",L25,F26*$V$6*(100/$V$5)) | M26: =IF(G26="",M25,(F26-$F$5)/G26) -> 1 | R26: =IF(F26="","",(F26-(E26*$V$71+$V$72))*100/(MAX($F$5:$F$105)*0.9)) | U26: SNR MAX(Saturation) | V26: =MAX(L6:L105) -> 0 | W26: =MAX(M6:M105) -> 1
E27: =IF(F27="","",E26+1) | F27: =IF(G27="","",B27) | G27: =IF(SUM($H$5:H26)<1,C27,"") | H27: =IF(MAX($C$5:$C$105)=C27,1,"") -> 1 | I27: =C27^2-$C$5^2 -> 0 | J27: =IF(AND($V$40>F27,NOT(G27="")),F27,"") -> #N/A | K27: =IF(AND($V$40>F27,NOT(G27="")),I27,"") -> #N/A | L27: =IF(G27="",L26,F27*$V$6*(100/$V$5)) | M27: =IF(G27="",M26,(F27-$F$5)/G27) -> 1 | R27: =IF(F27="","",(F27-(E27*$V$71+$V$72))*100/(MAX($F$5:$F$105)*0.9)) | U27: theor.limit | V27: 1 | W27: =SQRT(V27) -> 1
E28: =IF(F28="","",E27+1) | F28: =IF(G28="","",B28) | G28: =IF(SUM($H$5:H27)<1,C28,"") | H28: =IF(MAX($C$5:$C$105)=C28,1,"") -> 1 | I28: =C28^2-$C$5^2 -> 0 | J28: =IF(AND($V$40>F28,NOT(G28="")),F28,"") -> #N/A | K28: =IF(AND($V$40>F28,NOT(G28="")),I28,"") -> #N/A | L28: =IF(G28="",L27,F28*$V$6*(100/$V$5)) | M28: =IF(G28="",M27,(F28-$F$5)/G28) -> 1 | R28: =IF(F28="","",(F28-(E28*$V$71+$V$72))*100/(MAX($F$5:$F$105)*0.9)) | V28: 1000000 | W28: =SQRT(V28) -> 1000
E29: =IF(F29="","",E28+1) | F29: =IF(G29="","",B29) | G29: =IF(SUM($H$5:H28)<1,C29,"") | H29: =IF(MAX($C$5:$C$105)=C29,1,"") -> 1 | I29: =C29^2-$C$5^2 -> 0 | J29: =IF(AND($V$40>F29,NOT(G29="")),F29,"") -> #N/A | K29: =IF(AND($V$40>F29,NOT(G29="")),I29,"") -> #N/A | L29: =IF(G29="",L28,F29*$V$6*(100/$V$5)) | M29: =IF(G29="",M28,(F29-$F$5)/G29) -> 1 | R29: =IF(F29="","",(F29-(E29*$V$71+$V$72))*100/(MAX($F$5:$F$105)*0.9))
E30: =IF(F30="","",E29+1) | F30: =IF(G30="","",B30) | G30: =IF(SUM($H$5:H29)<1,C30,"") | H30: =IF(MAX($C$5:$C$105)=C30,1,"") -> 1 | I30: =C30^2-$C$5^2 -> 0 | J30: =IF(AND($V$40>F30,NOT(G30="")),F30,"") -> #N/A | K30: =IF(AND($V$40>F30,NOT(G30="")),I30,"") -> #N/A | L30: =IF(G30="",L29,F30*$V$6*(100/$V$5)) | M30: =IF(G30="",M29,(F30-$F$5)/G30) -> 1 | R30: =IF(F30="","",(F30-(E30*$V$71+$V$72))*100/(MAX($F$5:$F$105)*0.9))
E31: =IF(F31="","",E30+1) | F31: =IF(G31="","",B31) | G31: =IF(SUM($H$5:H30)<1,C31,"") | H31: =IF(MAX($C$5:$C$105)=C31,1,"") -> 1 | I31: =C31^2-$C$5^2 -> 0 | J31: =IF(AND($V$40>F31,NOT(G31="")),F31,"") -> #N/A | K31: =IF(AND($V$40>F31,NOT(G31="")),I31,"") -> #N/A | L31: =IF(G31="",L30,F31*$V$6*(100/$V$5)) | M31: =IF(G31="",M30,(F31-$F$5)/G31) -> 1 | R31: =IF(F31="","",(F31-(E31*$V$71+$V$72))*100/(MAX($F$5:$F$105)*0.9))
E32: =IF(F32="","",E31+1) | F32: =IF(G32="","",B32) | G32: =IF(SUM($H$5:H31)<1,C32,"") | H32: =IF(MAX($C$5:$C$105)=C32,1,"") -> 1 | I32: =C32^2-$C$5^2 -> 0 | J32: =IF(AND($V$40>F32,NOT(G32="")),F32,"") -> #N/A | K32: =IF(AND($V$40>F32,NOT(G32="")),I32,"") -> #N/A | L32: =IF(G32="",L31,F32*$V$6*(100/$V$5)) | M32: =IF(G32="",M31,(F32-$F$5)/G32) -> 1 | R32: =IF(F32="","",(F32-(E32*$V$71+$V$72))*100/(MAX($F$5:$F$105)*0.9))
E33: =IF(F33="","",E32+1) | F33: =IF(G33="","",B33) | G33: =IF(SUM($H$5:H32)<1,C33,"") | H33: =IF(MAX($C$5:$C$105)=C33,1,"") -> 1 | I33: =C33^2-$C$5^2 -> 0 | J33: =IF(AND($V$40>F33,NOT(G33="")),F33,"") -> #N/A | K33: =IF(AND($V$40>F33,NOT(G33="")),I33,"") -> #N/A | L33: =IF(G33="",L32,F33*$V$6*(100/$V$5)) | M33: =IF(G33="",M32,(F33-$F$5)/G33) -> 1 | R33: =IF(F33="","",(F33-(E33*$V$71+$V$72))*100/(MAX($F$5:$F$105)*0.9))
E34: =IF(F34="","",E33+1) | F34: =IF(G34="","",B34) | G34: =IF(SUM($H$5:H33)<1,C34,"") | H34: =IF(MAX($C$5:$C$105)=C34,1,"") -> 1 | I34: =C34^2-$C$5^2 -> 0 | J34: =IF(AND($V$40>F34,NOT(G34="")),F34,"") -> #N/A | K34: =IF(AND($V$40>F34,NOT(G34="")),I34,"") -> #N/A | L34: =IF(G34="",L33,F34*$V$6*(100/$V$5)) | M34: =IF(G34="",M33,(F34-$F$5)/G34) -> 1 | R34: =IF(F34="","",(F34-(E34*$V$71+$V$72))*100/(MAX($F$5:$F$105)*0.9))
E35: =IF(F35="","",E34+1) | F35: =IF(G35="","",B35) | G35: =IF(SUM($H$5:H34)<1,C35,"") | H35: =IF(MAX($C$5:$C$105)=C35,1,"") -> 1 | I35: =C35^2-$C$5^2 -> 0 | J35: =IF(AND($V$40>F35,NOT(G35="")),F35,"") -> #N/A | K35: =IF(AND($V$40>F35,NOT(G35="")),I35,"") -> #N/A | L35: =IF(G35="",L34,F35*$V$6*(100/$V$5)) | M35: =IF(G35="",M34,(F35-$F$5)/G35) -> 1 | R35: =IF(F35="","",(F35-(E35*$V$71+$V$72))*100/(MAX($F$5:$F$105)*0.9))
E36: =IF(F36="","",E35+1) | F36: =IF(G36="","",B36) | G36: =IF(SUM($H$5:H35)<1,C36,"") | H36: =IF(MAX($C$5:$C$105)=C36,1,"") -> 1 | I36: =C36^2-$C$5^2 -> 0 | J36: =IF(AND($V$40>F36,NOT(G36="")),F36,"") -> #N/A | K36: =IF(AND($V$40>F36,NOT(G36="")),I36,"") -> #N/A | L36: =IF(G36="",L35,F36*$V$6*(100/$V$5)) | M36: =IF(G36="",M35,(F36-$F$5)/G36) -> 1 | R36: =IF(F36="","",(F36-(E36*$V$71+$V$72))*100/(MAX($F$5:$F$105)*0.9))
E37: =IF(F37="","",E36+1) | F37: =IF(G37="","",B37) | G37: =IF(SUM($H$5:H36)<1,C37,"") | H37: =IF(MAX($C$5:$C$105)=C37,1,"") -> 1 | I37: =C37^2-$C$5^2 -> 0 | J37: =IF(AND($V$40>F37,NOT(G37="")),F37,"") -> #N/A | K37: =IF(AND($V$40>F37,NOT(G37="")),I37,"") -> #N/A | L37: =IF(G37="",L36,F37*$V$6*(100/$V$5)) | M37: =IF(G37="",M36,(F37-$F$5)/G37) -> 1 | R37: =IF(F37="","",(F37-(E37*$V$71+$V$72))*100/(MAX($F$5:$F$105)*0.9))
E38: =IF(F38="","",E37+1) | F38: =IF(G38="","",B38) | G38: =IF(SUM($H$5:H37)<1,C38,"") | H38: =IF(MAX($C$5:$C$105)=C38,1,"") -> 1 | I38: =C38^2-$C$5^2 -> 0 | J38: =IF(AND($V$40>F38,NOT(G38="")),F38,"") -> #N/A | K38: =IF(AND($V$40>F38,NOT(G38="")),I38,"") -> #N/A | L38: =IF(G38="",L37,F38*$V$6*(100/$V$5)) | M38: =IF(G38="",M37,(F38-$F$5)/G38) -> 1 | R38: =IF(F38="","",(F38-(E38*$V$71+$V$72))*100/(MAX($F$5:$F$105)*0.9)) | U38: 항목 | V38: X | W38: Y
E39: =IF(F39="","",E38+1) | F39: =IF(G39="","",B39) | G39: =IF(SUM($H$5:H38)<1,C39,"") | H39: =IF(MAX($C$5:$C$105)=C39,1,"") -> 1 | I39: =C39^2-$C$5^2 -> 0 | J39: =IF(AND($V$40>F39,NOT(G39="")),F39,"") -> #N/A | K39: =IF(AND($V$40>F39,NOT(G39="")),I39,"") -> #N/A | L39: =IF(G39="",L38,F39*$V$6*(100/$V$5)) | M39: =IF(G39="",M38,(F39-$F$5)/G39) -> 1 | R39: =IF(F39="","",(F39-(E39*$V$71+$V$72))*100/(MAX($F$5:$F$105)*0.9)) | U39: fit Line | V39: 0 | W39: =SQRT(V39) -> 0
E40: =IF(F40="","",E39+1) | F40: =IF(G40="","",B40) | G40: =IF(SUM($H$5:H39)<1,C40,"") | H40: =IF(MAX($C$5:$C$105)=C40,1,"") -> 1 | I40: =C40^2-$C$5^2 -> 0 | J40: =IF(AND($V$40>F40,NOT(G40="")),F40,"") -> #N/A | K40: =IF(AND($V$40>F40,NOT(G40="")),I40,"") -> #N/A | L40: =IF(G40="",L39,F40*$V$6*(100/$V$5)) | M40: =IF(G40="",M39,(F40-$F$5)/G40) -> 1 | R40: =IF(F40="","",(F40-(E40*$V$71+$V$72))*100/(MAX($F$5:$F$105)*0.9)) | V40: =INDEX(F5:F105,(MATCH(MAX(F5:F105),F5:F105,0))*0.7,0) -> #N/A | W40: =V40/V6 -> #N/A
E41: =IF(F41="","",E40+1) | F41: =IF(G41="","",B41) | G41: =IF(SUM($H$5:H40)<1,C41,"") | H41: =IF(MAX($C$5:$C$105)=C41,1,"") -> 1 | I41: =C41^2-$C$5^2 -> 0 | J41: =IF(AND($V$40>F41,NOT(G41="")),F41,"") -> #N/A | K41: =IF(AND($V$40>F41,NOT(G41="")),I41,"") -> #N/A | L41: =IF(G41="",L40,F41*$V$6*(100/$V$5)) | M41: =IF(G41="",M40,(F41-$F$5)/G41) -> 1 | R41: =IF(F41="","",(F41-(E41*$V$71+$V$72))*100/(MAX($F$5:$F$105)*0.9)) | U41: Saturation Line | V41: =MAX(F5:F103) -> 0 | W41: =(MAX(C5:C103))^2 -> 0
...

Sheet Linearity HG
A2: Input Data | E2: Output | U2: Output Data
A3: Exp/ Light Level | B3: Gray Value (uy-Uy.dark) | C3: Temporal STD | D3: Total STD | E3: Index | F3: Gray Value (uy-Uy.dark) | G3: STD | H3: STD CHK | I3: Variance gray | J3: Variance Fit | L3: photons | M3: SNR(linear) | N3: Linearity Error(%) | U3: Exp/ Light Level | V3: Gray Value (uy-Uy.dark) | W3: Temporal STD | X3: Total STD
H4: STD CHK | J4: GrayValue | K4: Variance slop
A5: 2 | B5: 7.27 | C5: 1.31 | D5: 1.75 | E5: 0 | F5: =IF(G5="","",B5) -> 7.27 | G5: =IF(SUM($H4:H$5)<1,C5,"") -> 1.31 | H5: =IF(MAX($C$5:$C$105)=C5,1,"") | I5: =C5^2-$C$5^2 -> 0 | J5: =IF(AND($R$40>F5,NOT(G5="")),F5,"") -> 7.27 | K5: =IF(AND($R$40>F5,NOT(G5="")),I5,"") -> 0 | L5: =IF(G5="","",G5*$R$6*(100/$R$5)) -> 18.390127 | M5: 1 | N5: =IF(F5="","",(F5-(E5*$R$71+$R$72))*100/(MAX($F$5:$F$105)*0.9)) -> 1.1783326 | Q5: Quamtum Eppiciency | R5: 88.4 | U5: 2 | V5: =B5*$R$8 -> #N/A | W5: =C5*$R$8 -> #N/A | X5: =D5*$R$8 -> #N/A
A6: 600 | B6: 13.26 | C6: 1.45 | D6: 1.81 | E6: =IF(F6="","",E5+1) -> 1 | F6: =IF(G6="","",B6) -> 13.26 | G6: =IF(SUM($H5:H$5)<1,C6,"") -> 1.45 | H6: =IF(MAX($C$5:$C$105)=C6,1,"") | I6: =C6^2-$C$5^2 -> 0.3864 | J6: =IF(AND($R$40>F6,NOT(G6="")),F6,"") -> 13.26 | K6: =IF(AND($R$40>F6,NOT(G6="")),I6,"") -> 0.3864 | L6: =IF(G6="",L5,F6*$R$6*(100/$R$5)) -> 186.14739 | M6: =IF(G6="",M5,(F6-$F$5)/G6) -> 4.1310345 | N6: =IF(F6="","",(F6-(E6*$R$71+$R$72))*100/(MAX($F$5:$F$105)*0.9)) -> 0.60085702 | Q6: System Gain LG | R6: =1/((MATCH(MAX(K5:K105),K5:K105)*SUMPRODUCT(J5:J105,K5:K105)-SUM(J5:J105)*SUM(K5:K105))/(MATCH(MAX(K5:K105),K5:K105)*SUMSQ(J5:J105) - SUM(J5:J105)^2)) -> 12.409826 | U6: 600 | V6: =B6*$R$8 -> #N/A | W6: =C6*$R$8 -> #N/A | X6: =D6*$R$8 -> #N/A
A7: 1200 | B7: 20.41 | C7: 1.64 | D7: 1.95 | E7: =IF(F7="","",E6+1) -> 2 | F7: =IF(G7="","",B7) -> 20.41 | G7: =IF(SUM($H$5:H6)<1,C7,"") -> 1.64 | H7: =IF(MAX($C$5:$C$105)=C7,1,"") | I7: =C7^2-$C$5^2 -> 0.9735 | J7: =IF(AND($R$40>F7,NOT(G7="")),F7,"") -> 20.41 | K7: =IF(AND($R$40>F7,NOT(G7="")),I7,"") -> 0.9735 | L7: =IF(G7="",L6,F7*$R$6*(100/$R$5)) -> 286.52099 | M7: =IF(G7="",M6,(F7-$F$5)/G7) -> 8.0121951 | N7: =IF(F7="","",(F7-(E7*$R$71+$R$72))*100/(MAX($F$5:$F$105)*0.9)) -> 0.56280087 | Q7: System Gain HG | R7: ='Linearity Data'!V6 -> #N/A | U7: 1200 | V7: =B7*$R$8 -> #N/A | W7: =C7*$R$8 -> #N/A | X7: =D7*$R$8 -> #N/A
A8: 1800 | B8: 27.38 | C8: 1.81 | D8: 2.14 | E8: =IF(F8="","",E7+1) -> 3 | F8: =IF(G8="","",B8) -> 27.38 | G8: =IF(SUM($H$5:H7)<1,C8,"") -> 1.81 | H8: =IF(MAX($C$5:$C$105)=C8,1,"") | I8: =C8^2-$C$5^2 -> 1.56 | J8: =IF(AND($R$40>F8,NOT(G8="")),F8,"") -> 27.38 | K8: =IF(AND($R$40>F8,NOT(G8="")),I8,"") -> 1.56 | L8: =IF(G8="",L7,F8*$R$6*(100/$R$5)) -> 384.36769 | M8: =IF(G8="",M7,(F8-$F$5)/G8) -> 11.110497 | N8: =IF(F8="","",(F8-(E8*$R$71+$R$72))*100/(MAX($F$5:$F$105)*0.9)) -> 0.44104169 | Q8: LG HG Ratio | R8: =R6/R7 -> #N/A | U8: 1800 | V8: =B8*$R$8 -> #N/A | W8: =C8*$R$8 -> #N/A | X8: =D8*$R$8 -> #N/A
A9: 2400 | B9: 34.06 | C9: 2.07 | D9: 2.35 | E9: =IF(F9="","",E8+1) -> 4 | F9: =IF(G9="","",B9) -> 34.06 | G9: =IF(SUM($H$5:H8)<1,C9,"") -> 2.07 | H9: =IF(MAX($C$5:$C$105)=C9,1,"") | I9: =C9^2-$C$5^2 -> 2.5688 | J9: =IF(AND($R$40>F9,NOT(G9="")),F9,"") -> 34.06 | K9: =IF(AND($R$40>F9,NOT(G9="")),I9,"") -> 2.5688 | L9: =IF(G9="",L8,F9*$R$6*(100/$R$5)) -> 478.1433 | M9: =IF(G9="",M8,(F9-$F$5)/G9) -> 12.942029 | N9: =IF(F9="","",(F9-(E9*$R$71+$R$72))*100/(MAX($F$5:$F$105)*0.9)) -> 0.18442765 | U9: 2400 | V9: =B9*$R$8 -> #N/A | W9: =C9*$R$8 -> #N/A | X9: =D9*$R$8 -> #N/A
A10: 3000 | B10: 41.44 | C10: 2.16 | D10: 2.43 | E10: =IF(F10="","",E9+1) -> 5 | F10: =IF(G10="","",B10) -> 41.44 | G10: =IF(SUM($H$5:H9)<1,C10,"") -> 2.16 | H10: =IF(MAX($C$5:$C$105)=C10,1,"") | I10: =C10^2-$C$5^2 -> 2.9495 | J10: =IF(AND($R$40>F10,NOT(G10="")),F10,"") -> 41.44 | K10: =IF(AND($R$40>F10,NOT(G10="")),I10,"") -> 2.9495 | L10: =IF(G10="",L9,F10*$R$6*(100/$R$5)) -> 581.74569 | M10: =IF(G10="",M9,(F10-$F$5)/G10) -> 15.819444 | N10: =IF(F10="","",(F10-(E10*$R$71+$R$72))*100/(MAX($F$5:$F$105)*0.9)) -> 0.25332535 | Q10: DSNU1288 | R10: =SQRT(R13)*R6 -> 14.399677 | S10: e- | U10: 3000 | V10: =B10*$R$8 -> #N/A | W10: =C10*$R$8 -> #N/A | X10: =D10*$R$8 -> #N/A
A11: 3600 | B11: 48.68 | C11: 2.31 | D11: 2.61 | E11: =IF(F11="","",E10+1) -> 6 | F11: =IF(G11="","",B11) -> 48.68 | G11: =IF(SUM($H$5:H10)<1,C11,"") -> 2.31 | H11: =IF(MAX($C$5:$C$105)=C11,1,"") | I11: =C11^2-$C$5^2 -> 3.62 | J11: =IF(AND($R$40>F11,NOT(G11="")),F11,"") -> 48.68 | K11: =IF(AND($R$40>F11,NOT(G11="")),I11,"") -> 3.62 | L11: =IF(G11="",L10,F11*$R$6*(100/$R$5)) -> 683.38273 | M11: =IF(G11="",M10,(F11-$F$5)/G11) -> 17.926407 | N11: =IF(F11="","",(F11-(E11*$R$71+$R$72))*100/(MAX($F$5:$F$105)*0.9)) -> 0.25712071 | Q11: PRNU1288 | R11: =SQRT(R14-R13)*100/(R15-R16) -> 1.192145 | S11: % | U11: 3600 | V11: =B11*$R$8 -> #N/A | W11: =C11*$R$8 -> #N/A | X11: =D11*$R$8 -> #N/A
A12: 4200 | B12: 55.44 | C12: 2.41 | D12: 2.74 | E12: =IF(F12="","",E11+1) -> 7 | F12: =IF(G12="","",B12) -> 55.44 | G12: =IF(SUM($H$5:H11)<1,C12,"") -> 2.41 | H12: =IF(MAX($C$5:$C$105)=C12,1,"") | I12: =C12^2-$C$5^2 -> 4.092 | J12: =IF(AND($R$40>F12,NOT(G12="")),F12,"") -> 55.44 | K12: =IF(AND($R$40>F12,NOT(G12="")),I12,"") -> 4.092 | L12: =IF(G12="",L11,F12*$R$6*(100/$R$5)) -> 778.2814 | M12: =IF(G12="",M11,(F12-$F$5)/G12) -> 19.987552 | N12: =IF(F12="","",(F12-(E12*$R$71+$R$72))*100/(MAX($F$5:$F$105)*0.9)) -> 0.037708012 | U12: 4200 | V12: =B12*$R$8 -> #N/A | W12: =C12*$R$8 -> #N/A | X12: =D12*$R$8 -> #N/A
A13: 4800 | B13: 62.46 | C13: 2.52 | D13: 2.83 | E13: =IF(F13="","",E12+1) -> 8 | F13: =IF(G13="","",B13) -> 62.46 | G13: =IF(SUM($H$5:H12)<1,C13,"") -> 2.52 | H13: =IF(MAX($C$5:$C$105)=C13,1,"") | I13: =C13^2-$C$5^2 -> 4.6343 | J13: =IF(AND($R$40>F13,NOT(G13="")),F13,"") -> 62.46 | K13: =IF(AND($R$40>F13,NOT(G13="")),I13,"") -> 4.6343 | L13: =IF(G13="",L12,F13*$R$6*(100/$R$5)) -> 876.83002 | M13: =IF(G13="",M12,(F13-$F$5)/G13) -> 21.900794 | N13: =IF(F13="","",(F13-(E13*$R$71+$R$72))*100/(MAX($F$5:$F$105)*0.9)) -> -0.060800323 | Q13: Sy.dark^2 | R13: =D5^2-C5^2 -> 1.3464 | U13: 4800 | V13: =B13*$R$8 -> #N/A | W13: =C13*$R$8 -> #N/A | X13: =D13*$R$8 -> #N/A
A14: 5400 | B14: 69.19 | C14: 2.66 | D14: 3.02 | E14: =IF(F14="","",E13+1) -> 9 | F14: =IF(G14="","",B14) -> 69.19 | G14: =IF(SUM($H$5:H13)<1,C14,"") -> 2.66 | H14: =IF(MAX($C$5:$C$105)=C14,1,"") | I14: =C14^2-$C$5^2 -> 5.3595 | J14: =IF(AND($R$40>F14,NOT(G14="")),F14,"") -> 69.19 | K14: =IF(AND($R$40>F14,NOT(G14="")),I14,"") -> 5.3595 | L14: =IF(G14="",L13,F14*$R$6*(100/$R$5)) -> 971.30754 | M14: =IF(G14="",M13,(F14-$F$5)/G14) -> 23.278195 | N14: =IF(F14="","",(F14-(E14*$R$71+$R$72))*100/(MAX($F$5:$F$105)*0.9)) -> -0.29416353 | Q14: Sy.50^2 | R14: =INDEX(D5:D105,(MATCH(MAX(F5:F105),F5:F105,0)+F5)*0.5,0)^2-INDEX(C5:C105,(MATCH(MAX(F5:F105),F5:F105,0)+F5)*0.5,0)^2 -> 3.86 | U14: 5400 | V14: =B14*$R$8 -> #N/A | W14: =C14*$R$8 -> #N/A | X14: =D14*$R$8 -> #N/A
A15: 6000 | B15: 76.53 | C15: 2.71 | D15: 3.09 | E15: =IF(F15="","",E14+1) -> 10 | F15: =IF(G15="","",B15) -> 76.53 | G15: =IF(SUM($H$5:H14)<1,C15,"") -> 2.71 | H15: =IF(MAX($C$5:$C$105)=C15,1,"") | I15: =C15^2-$C$5^2 -> 5.628 | J15: =IF(AND($R$40>F15,NOT(G15="")),F15,"") -> 76.53 | K15: =IF(AND($R$40>F15,NOT(G15="")),I15,"") -> 5.628 | L15: =IF(G15="",L14,F15*$R$6*(100/$R$5)) -> 1074.3484 | M15: =IF(G15="",M14,(F15-$F$5)/G15) -> 25.557196 | N15: =IF(F15="","",(F15-(E15*$R$71+$R$72))*100/(MAX($F$5:$F$105)*0.9)) -> -0.24386649 | Q15: uy.50 | R15: =INDEX(B5:B105,(MATCH(MAX(F5:F105),F5:F105,0)+F5)*0.5,0) -> 140.26 | U15: 6000 | V15: =B15*$R$8 -> #N/A | W15: =C15*$R$8 -> #N/A | X15: =D15*$R$8 -> #N/A
A16: 6600 | B16: 83.81 | C16: 2.82 | D16: 3.2 | E16: =IF(F16="","",E15+1) -> 11 | F16: =IF(G16="","",B16) -> 83.81 | G16: =IF(SUM($H$5:H15)<1,C16,"") -> 2.82 | H16: =IF(MAX($C$5:$C$105)=C16,1,"") | I16: =C16^2-$C$5^2 -> 6.2363 | J16: =IF(AND($R$40>F16,NOT(G16="")),F16,"") -> 83.81 | K16: =IF(AND($R$40>F16,NOT(G16="")),I16,"") -> 6.2363 | L16: =IF(G16="",L15,F16*$R$6*(100/$R$5)) -> 1176.547 | M16: =IF(G16="",M15,(F16-$F$5)/G16) -> 27.141844 | N16: =IF(F16="","",(F16-(E16*$R$71+$R$72))*100/(MAX($F$5:$F$105)*0.9)) -> -0.22147046 | Q16: uy.dark | R16: =B5 -> 7.27 | U16: 6600 | V16: =B16*$R$8 -> #N/A | W16: =C16*$R$8 -> #N/A | X16: =D16*$R$8 -> #N/A
A17: 7200 | B17: 91 | C17: 2.94 | D17: 3.34 | E17: =IF(F17="","",E16+1) -> 12 | F17: =IF(G17="","",B17) -> 91 | G17: =IF(SUM($H$5:H16)<1,C17,"") -> 2.94 | H17: =IF(MAX($C$5:$C$105)=C17,1,"") | I17: =C17^2-$C$5^2 -> 6.9275 | J17: =IF(AND($R$40>F17,NOT(G17="")),F17,"") -> 91 | K17: =IF(AND($R$40>F17,NOT(G17="")),I17,"") -> 6.9275 | L17: =IF(G17="",L16,F17*$R$6*(100/$R$5)) -> 1277.4821 | M17: =IF(G17="",M16,(F17-$F$5)/G17) -> 28.479592 | N17: =IF(F17="","",(F17-(E17*$R$71+$R$72))*100/(MAX($F$5:$F$105)*0.9)) -> -0.24092594 | U17: 7200 | V17: =B17*$R$8 -> #N/A | W17: =C17*$R$8 -> #N/A | X17: =D17*$R$8 -> #N/A
A18: 7800 | B18: 98 | C18: 3.07 | D18: 3.49 | E18: =IF(F18="","",E17+1) -> 13 | F18: =IF(G18="","",B18) -> 98 | G18: =IF(SUM($H$5:H17)<1,C18,"") -> 3.07 | H18: =IF(MAX($C$5:$C$105)=C18,1,"") | I18: =C18^2-$C$5^2 -> 7.7088 | J18: =IF(AND($R$40>F18,NOT(G18="")),F18,"") -> 98 | K18: =IF(AND($R$40>F18,NOT(G18="")),I18,"") -> 7.7088 | L18: =IF(G18="",L17,F18*$R$6*(100/$R$5)) -> 1375.75 | M18: =IF(G18="",M17,(F18-$F$5)/G18) -> 29.553746 | N18: =IF(F18="","",(F18-(E18*$R$71+$R$72))*100/(MAX($F$5:$F$105)*0.9)) -> -0.34873461 | U18: 7800 | V18: =B18*$R$8 -> #N/A | W18: =C18*$R$8 -> #N/A | X18: =D18*$R$8 -> #N/A
A19: 8400 | B19: 105.17 | C19: 3.16 | D19: 3.57 | E19: =IF(F19="","",E18+1) -> 14 | F19: =IF(G19="","",B19) -> 105.17 | G19: =IF(SUM($H$5:H18)<1,C19,"") -> 3.16 | H19: =IF(MAX($C$5:$C$105)=C19,1,"") | I19: =C19^2-$C$5^2 -> 8.2695 | J19: =IF(AND($R$40>F19,NOT(G19="")),F19,"") -> 105.17 | K19: =IF(AND($R$40>F19,NOT(G19="")),I19,"") -> 8.2695 | L19: =IF(G19="",L18,F19*$R$6*(100/$R$5)) -> 1476.4043 | M19: =IF(G19="",M18,(F19-$F$5)/G19) -> 30.981013 | N19: =IF(F19="","",(F19-(E19*$R$71+$R$72))*100/(MAX($F$5:$F$105)*0.9)) -> -0.37749043 | U19: 8400 | V19: =B19*$R$8 -> #N/A | W19: =C19*$R$8 -> #N/A | X19: =D19*$R$8 -> #N/A
A20: 9000 | B20: 112.1 | C20: 3.21 | D20: 3.67 | E20: =IF(F20="","",E19+1) -> 15 | F20: =IF(G20="","",B20) -> 112.1 | G20: =IF(SUM($H$5:H19)<1,C20,"") -> 3.21 | H20: =IF(MAX($C$5:$C$105)=C20,1,"") | I20: =C20^2-$C$5^2 -> 8.588 | J20: =IF(AND($R$40>F20,NOT(G20="")),F20,"") -> 112.1 | K20: =IF(AND($R$40>F20,NOT(G20="")),I20,"") -> 8.588 | L20: =IF(G20="",L19,F20*$R$6*(100/$R$5)) -> 1573.6895 | M20: =IF(G20="",M19,(F20-$F$5)/G20) -> 32.657321 | N20: =IF(F20="","",(F20-(E20*$R$71+$R$72))*100/(MAX($F$5:$F$105)*0.9)) -> -0.51785028 | U20: 9000 | V20: =B20*$R$8 -> #N/A | W20: =C20*$R$8 -> #N/A | X20: =D20*$R$8 -> #N/A
A21: 9600 | B21: 119 | C21: 3.29 | D21: 3.78 | E21: =IF(F21="","",E20+1) -> 16 | F21: =IF(G21="","",B21) -> 119 | G21: =IF(SUM($H$5:H20)<1,C21,"") -> 3.29 | H21: =IF(MAX($C$5:$C$105)=C21,1,"") | I21: =C21^2-$C$5^2 -> 9.108 | J21: =IF(AND($R$40>F21,NOT(G21="")),F21,"") -> 119 | K21: =IF(AND($R$40>F21,NOT(G21="")),I21,"") -> 9.108 | L21: =IF(G21="",L20,F21*$R$6*(100/$R$5)) -> 1670.5535 | M21: =IF(G21="",M20,(F21-$F$5)/G21) -> 33.960486 | N21: =IF(F21="","",(F21-(E21*$R$71+$R$72))*100/(MAX($F$5:$F$105)*0.9)) -> -0.67216063 | U21: 9600 | V21: =B21*$R$8 -> #N/A | W21: =C21*$R$8 -> #N/A | X21: =D21*$R$8 -> #N/A
A22: 10200 | B22: 126.46 | C22: 3.34 | D22: 3.87 | E22: =IF(F22="","",E21+1) -> 17 | F22: =IF(G22="","",B22) -> 126.46 | G22: =IF(SUM($H$5:H21)<1,C22,"") -> 3.34 | H22: =IF(MAX($C$5:$C$105)=C22,1,"") | I22: =C22^2-$C$5^2 -> 9.4395 | J22: =IF(AND($R$40>F22,NOT(G22="")),F22,"") -> 126.46 | K22: =IF(AND($R$40>F22,NOT(G22="")),I22,"") -> 9.4395 | L22: =IF(G22="",L21,F22*$R$6*(100/$R$5)) -> 1775.279 | M22: =IF(G22="",M21,(F22-$F$5)/G22) -> 35.685629 | N22: =IF(F22="","",(F22-(E22*$R$71+$R$72))*100/(MAX($F$5:$F$105)*0.9)) -> -0.56606158 | U22: 10200 | V22: =B22*$R$8 -> #N/A | W22: =C22*$R$8 -> #N/A | X22: =D22*$R$8 -> #N/A
A23: 10800 | B23: 133.39 | C23: 3.44 | D23: 3.98 | E23: =IF(F23="","",E22+1) -> 18 | F23: =IF(G23="","",B23) -> 133.39 | G23: =IF(SUM($H$5:H22)<1,C23,"") -> 3.44 | H23: =IF(MAX($C$5:$C$105)=C23,1,"") | I23: =C23^2-$C$5^2 -> 10.1175 | J23: =IF(AND($R$40>F23,NOT(G23="")),F23,"") -> 133.39 | K23: =IF(AND($R$40>F23,NOT(G23="")),I23,"") -> 10.1175 | L23: =IF(G23="",L22,F23*$R$6*(100/$R$5)) -> 1872.5641 | M23: =IF(G23="",M22,(F23-$F$5)/G23) -> 36.662791 | N23: =IF(F23="","",(F23-(E23*$R$71+$R$72))*100/(MAX($F$5:$F$105)*0.9)) -> -0.70642142 | U23: 10800 | V23: =B23*$R$8 -> #N/A | W23: =C23*$R$8 -> #N/A | X23: =D23*$R$8 -> #N/A
A24: 11400 | B24: 140.26 | C24: 3.61 | D24: 4.11 | E24: =IF(F24="","",E23+1) -> 19 | F24: =IF(G24="","",B24) -> 140.26 | G24: =IF(SUM($H$5:H23)<1,C24,"") -> 3.61 | H24: =IF(MAX($C$5:$C$105)=C24,1,"") | I24: =C24^2-$C$5^2 -> 11.316 | J24: =IF(AND($R$40>F24,NOT(G24="")),F24,"") -> 140.26 | K24: =IF(AND($R$40>F24,NOT(G24="")),I24,"") -> 11.316 | L24: =IF(G24="",L23,F24*$R$6*(100/$R$5)) -> 1969.007 | M24: =IF(G24="",M23,(F24-$F$5)/G24) -> 36.839335 | N24: =IF(F24="","",(F24-(E24*$R$71+$R$72))*100/(MAX($F$5:$F$105)*0.9)) -> -0.87468228 | Q24: 항목 | R24: photon | S24: ratio | U24: 11400 | V24: =B24*$R$8 -> #N/A | W24: =C24*$R$8 -> #N/A | X24: =D24*$R$8 -> #N/A
A25: 12000 | B25: 148.22 | C25: 3.6 | D25: 4.2 | E25: =IF(F25="","",E24+1) -> 20 | F25: =IF(G25="","",B25) -> 148.22 | G25: =IF(SUM($H$5:H24)<1,C25,"") -> 3.6 | H25: =IF(MAX($C$5:$C$105)=C25,1,"") | I25: =C25^2-$C$5^2 -> 11.2439 | J25: =IF(AND($R$40>F25,NOT(G25="")),F25,"") -> 148.22 | K25: =IF(AND($R$40>F25,NOT(G25="")),I25,"") -> 11.2439 | L25: =IF(G25="",L24,F25*$R$6*(100/$R$5)) -> 2080.7516 | M25: =IF(G25="",M24,(F25-$F$5)/G25) -> 39.152778 | N25: =IF(F25="","",(F25-(E25*$R$71+$R$72))*100/(MAX($F$5:$F$105)*0.9)) -> -0.53607483 | Q25: SNR 1 | R25: =MIN(L4:L104) -> 18.390127 | S25: =MIN(M4:M104) -> 1 | U25: 12000 | V25: =B25*$R$8 -> #N/A | W25: =C25*$R$8 -> #N/A | X25: =D25*$R$8 -> #N/A
A26: 12600 | B26: 155.03 | C26: 3.67 | D26: 4.28 | E26: =IF(F26="","",E25+1) -> 21 | F26: =IF(G26="","",B26) -> 155.03 | G26: =IF(SUM($H$5:H25)<1,C26,"") -> 3.67 | H26: =IF(MAX($C$5:$C$105)=C26,1,"") | I26: =C26^2-$C$5^2 -> 11.7528 | J26: =IF(AND($R$40>F26,NOT(G26="")),F26,"") -> 155.03 | K26: =IF(AND($R$40>F26,NOT(G26="")),I26,"") -> 11.7528 | L26: =IF(G26="",L25,F26*$R$6*(100/$R$5)) -> 2176.3522 | M26: =IF(G26="",M25,(F26-$F$5)/G26) -> 40.26158 | N26: =IF(F26="","",(F26-(E26*$R$71+$R$72))*100/(MAX($F$5:$F$105)*0.9)) -> -0.73223669 | Q26: SNR MAX(Saturation) | R26: =MAX(L6:L105) -> 3354.303 | S26: =MAX(M6:M105) -> 52.77221 | U26: 12600 | V26: =B26*$R$8 -> #N/A | W26: =C26*$R$8 -> #N/A | X26: =D26*$R$8 -> #N/A
A27: 13200 | B27: 162.57 | C27: 3.73 | D27: 4.4 | E27: =IF(F27="","",E26+1) -> 22 | F27: =IF(G27="","",B27) -> 162.57 | G27: =IF(SUM($H$5:H26)<1,C27,"") -> 3.73 | H27: =IF(MAX($C$5:$C$105)=C27,1,"") | I27: =C27^2-$C$5^2 -> 12.1968 | J27: =IF(AND($R$40>F27,NOT(G27="")),F27,"") | K27: =IF(AND($R$40>F27,NOT(G27="")),I27,"") | L27: =IF(G27="",L26,F27*$R$6*(100/$R$5)) -> 2282.2007 | M27: =IF(G27="",M26,(F27-$F$5)/G27) -> 41.635389 | N27: =IF(F27="","",(F27-(E27*$R$71+$R$72))*100/(MAX($F$5:$F$105)*0.9)) -> -0.5889363 | Q27: theor.limit | R27: 1 | S27: =SQRT(R27) -> 1 | U27: 13200 | V27: =B27*$R$8 -> #N/A | W27: =C27*$R$8 -> #N/A | X27: =D27*$R$8 -> #N/A
A28: 13800 | B28: 170.29 | C28: 3.85 | D28: 4.54 | E28: =IF(F28="","",E27+1) -> 23 | F28: =IF(G28="","",B28) -> 170.29 | G28: =IF(SUM($H$5:H27)<1,C28,"") -> 3.85 | H28: =IF(MAX($C$5:$C$105)=C28,1,"") | I28: =C28^2-$C$5^2 -> 13.1064 | J28: =IF(AND($R$40>F28,NOT(G28="")),F28,"") | K28: =IF(AND($R$40>F28,NOT(G28="")),I28,"") | L28: =IF(G28="",L27,F28*$R$6*(100/$R$5)) -> 2390.5761 | M28: =IF(G28="",M27,(F28-$F$5)/G28) -> 42.342857 | N28: =IF(F28="","",(F28-(E28*$R$71+$R$72))*100/(MAX($F$5:$F$105)*0.9)) -> -0.36193289 | R28: 1000000 | S28: =SQRT(R28) -> 1000 | U28: 13800 | V28: =B28*$R$8 -> #N/A | W28: =C28*$R$8 -> #N/A | X28: =D28*$R$8 -> #N/A
A29: 14400 | B29: 177.92 | C29: 3.87 | D29: 4.63 | E29: =IF(F29="","",E28+1) -> 24 | F29: =IF(G29="","",B29) -> 177.92 | G29: =IF(SUM($H$5:H28)<1,C29,"") -> 3.87 | H29: =IF(MAX($C$5:$C$105)=C29,1,"") | I29: =C29^2-$C$5^2 -> 13.2608 | J29: =IF(AND($R$40>F29,NOT(G29="")),F29,"") | K29: =IF(AND($R$40>F29,NOT(G29="")),I29,"") | L29: =IF(G29="",L28,F29*$R$6*(100/$R$5)) -> 2497.6881 | M29: =IF(G29="",M28,(F29-$F$5)/G29) -> 44.095607 | N29: =IF(F29="","",(F29-(E29*$R$71+$R$72))*100/(MAX($F$5:$F$105)*0.9)) -> -0.17678098 | U29: 14400 | V29: =B29*$R$8 -> #N/A | W29: =C29*$R$8 -> #N/A | X29: =D29*$R$8 -> #N/A
A30: 15000 | B30: 184.76 | C30: 3.93 | D30: 4.73 | E30: =IF(F30="","",E29+1) -> 25 | F30: =IF(G30="","",B30) -> 184.76 | G30: =IF(SUM($H$5:H29)<1,C30,"") -> 3.93 | H30: =IF(MAX($C$5:$C$105)=C30,1,"") | I30: =C30^2-$C$5^2 -> 13.7288 | J30: =IF(AND($R$40>F30,NOT(G30="")),F30,"") | K30: =IF(AND($R$40>F30,NOT(G30="")),I30,"") | L30: =IF(G30="",L29,F30*$R$6*(100/$R$5)) -> 2593.7098 | M30: =IF(G30="",M29,(F30-$F$5)/G30) -> 45.16285 | N30: =IF(F30="","",(F30-(E30*$R$71+$R$72))*100/(MAX($F$5:$F$105)*0.9)) -> -0.35899234 | U30: 15000 | V30: =B30*$R$8 -> #N/A | W30: =C30*$R$8 -> #N/A | X30: =D30*$R$8 -> #N/A
A31: 15600 | B31: 192.96 | C31: 4.01 | D31: 4.82 | E31: =IF(F31="","",E30+1) -> 26 | F31: =IF(G31="","",B31) -> 192.96 | G31: =IF(SUM($H$5:H30)<1,C31,"") -> 4.01 | H31: =IF(MAX($C$5:$C$105)=C31,1,"") | I31: =C31^2-$C$5^2 -> 14.364 | J31: =IF(AND($R$40>F31,NOT(G31="")),F31,"") | K31: =IF(AND($R$40>F31,NOT(G31="")),I31,"") | L31: =IF(G31="",L30,F31*$R$6*(100/$R$5)) -> 2708.8236 | M31: =IF(G31="",M30,(F31-$F$5)/G31) -> 46.306733 | N31: =IF(F31="","",(F31-(E31*$R$71+$R$72))*100/(MAX($F$5:$F$105)*0.9)) -> 0.091219135 | U31: 15600 | V31: =B31*$R$8 -> #N/A | W31: =C31*$R$8 -> #N/A | X31: =D31*$R$8 -> #N/A
A32: 16200 | B32: 200.82 | C32: 4.15 | D32: 4.97 | E32: =IF(F32="","",E31+1) -> 27 | F32: =IF(G32="","",B32) -> 200.82 | G32: =IF(SUM($H$5:H31)<1,C32,"") -> 4.15 | H32: =IF(MAX($C$5:$C$105)=C32,1,"") | I32: =C32^2-$C$5^2 -> 15.5064 | J32: =IF(AND($R$40>F32,NOT(G32="")),F32,"") | K32: =IF(AND($R$40>F32,NOT(G32="")),I32,"") | L32: =IF(G32="",L31,F32*$R$6*(100/$R$5)) -> 2819.1643 | M32: =IF(G32="",M31,(F32-$F$5)/G32) -> 46.638554 | N32: =IF(F32="","",(F32-(E32*$R$71+$R$72))*100/(MAX($F$5:$F$105)*0.9)) -> 0.3833249 | U32: 16200 | V32: =B32*$R$8 -> #N/A | W32: =C32*$R$8 -> #N/A | X32: =D32*$R$8 -> #N/A
A33: 16800 | B33: 208.06 | C33: 4.17 | D33: 5.03 | E33: =IF(F33="","",E32+1) -> 28 | F33: =IF(G33="","",B33) -> 208.06 | G33: =IF(SUM($H$5:H32)<1,C33,"") -> 4.17 | H33: =IF(MAX($C$5:$C$105)=C33,1,"") | I33: =C33^2-$C$5^2 -> 15.6728 | J33: =IF(AND($R$40>F33,NOT(G33="")),F33,"") | K33: =IF(AND($R$40>F33,NOT(G33="")),I33,"") | L33: =IF(G33="",L32,F33*$R$6*(100/$R$5)) -> 2920.8014 | M33: =IF(G33="",M32,(F33-$F$5)/G33) -> 48.151079 | N33: =IF(F33="","",(F33-(E33*$R$71+$R$72))*100/(MAX($F$5:$F$105)*0.9)) -> 0.38712026 | U33: 16800 | V33: =B33*$R$8 -> #N/A | W33: =C33*$R$8 -> #N/A | X33: =D33*$R$8 -> #N/A
A34: 17400 | B34: 215.36 | C34: 4.18 | D34: 5.15 | E34: =IF(F34="","",E33+1) -> 29 | F34: =IF(G34="","",B34) -> 215.36 | G34: =IF(SUM($H$5:H33)<1,C34,"") -> 4.18 | H34: =IF(MAX($C$5:$C$105)=C34,1,"") | I34: =C34^2-$C$5^2 -> 15.7563 | J34: =IF(AND($R$40>F34,NOT(G34="")),F34,"") | K34: =IF(AND($R$40>F34,NOT(G34="")),I34,"") | L34: =IF(G34="",L33,F34*$R$6*(100/$R$5)) -> 3023.2807 | M34: =IF(G34="",M33,(F34-$F$5)/G34) -> 49.782297 | N34: =IF(F34="","",(F34-(E34*$R$71+$R$72))*100/(MAX($F$5:$F$105)*0.9)) -> 0.41881662 | U34: 17400 | V34: =B34*$R$8 -> #N/A | W34: =C34*$R$8 -> #N/A | X34: =D34*$R$8 -> #N/A
A35: 18000 | B35: 223.1 | C35: 4.27 | D35: 5.23 | E35: =IF(F35="","",E34+1) -> 30 | F35: =IF(G35="","",B35) -> 223.1 | G35: =IF(SUM($H$5:H34)<1,C35,"") -> 4.27 | H35: =IF(MAX($C$5:$C$105)=C35,1,"") | I35: =C35^2-$C$5^2 -> 16.5168 | J35: =IF(AND($R$40>F35,NOT(G35="")),F35,"") | K35: =IF(AND($R$40>F35,NOT(G35="")),I35,"") | L35: =IF(G35="",L34,F35*$R$6*(100/$R$5)) -> 3131.9369 | M35: =IF(G35="",M34,(F35-$F$5)/G35) -> 50.545667 | N35: =IF(F35="","",(F35-(E35*$R$71+$R$72))*100/(MAX($F$5:$F$105)*0.9)) -> 0.65512037 | U35: 18000 | V35: =B35*$R$8 -> #N/A | W35: =C35*$R$8 -> #N/A | X35: =D35*$R$8 -> #N/A
A36: 18600 | B36: 231.36 | C36: 4.34 | D36: 5.34 | E36: =IF(F36="","",E35+1) -> 31 | F36: =IF(G36="","",B36) -> 231.36 | G36: =IF(SUM($H$5:H35)<1,C36,"") -> 4.34 | H36: =IF(MAX($C$5:$C$105)=C36,1,"") | I36: =C36^2-$C$5^2 -> 17.1195 | J36: =IF(AND($R$40>F36,NOT(G36="")),F36,"") | K36: =IF(AND($R$40>F36,NOT(G36="")),I36,"") | L36: =IF(G36="",L35,F36*$R$6*(100/$R$5)) -> 3247.8929 | M36: =IF(G36="",M35,(F36-$F$5)/G36) -> 51.633641 | N36: =IF(F36="","",(F36-(E36*$R$71+$R$72))*100/(MAX($F$5:$F$105)*0.9)) -> 1.1332329 | U36: 18600 | V36: =B36*$R$8 -> #N/A | W36: =C36*$R$8 -> #N/A | X36: =D36*$R$8 -> #N/A
A37: 19200 | B37: 238.94 | C37: 4.39 | D37: 5.45 | E37: =IF(F37="","",E36+1) -> 32 | F37: =IF(G37="","",B37) -> 238.94 | G37: =IF(SUM($H$5:H36)<1,C37,"") -> 4.39 | H37: =IF(MAX($C$5:$C$105)=C37,1,"") -> 1 | I37: =C37^2-$C$5^2 -> 17.556 | J37: =IF(AND($R$40>F37,NOT(G37="")),F37,"") | K37: =IF(AND($R$40>F37,NOT(G37="")),I37,"") | L37: =IF(G37="",L36,F37*$R$6*(100/$R$5)) -> 3354.303 | M37: =IF(G37="",M36,(F37-$F$5)/G37) -> 52.77221 | N37: =IF(F37="","",(F37-(E37*$R$71+$R$72))*100/(MAX($F$5:$F$105)*0.9)) -> 1.2951339 | U37: 19200 | V37: =B37*$R$8 -> #N/A | W37: =C37*$R$8 -> #N/A | X37: =D37*$R$8 -> #N/A
